Workbook
Name daygrid: H+모니터링!z*7
Name daygrid: H+[0]!z*7
Name daypattern: {1,1,2,2,3,3,4,4,5,5,6,6,7}
Name daypattern: {1,1,2,2,3,3,4,4,5,5,6,6,7}
Name days: {0,1,2,3,4,5,6}
Name days: {0,1,2,3,4,5,6}
Name months: {"1월","2월","3월","4월","5월","6월","7월","8월","9월","10월","11월","12월"}
Name months: {"1월","2월","3월","4월","5월","6월","7월","8월","9월","10월","11월","12월"}
Name weeks: {0;1;2;3;4;5;6}
Name weeks: {0;1;2;3;4;5;6}
Name z: {0;1;2;3;4;5;6}
Name z: {0;1;2;3;4;5;6}
Name ㅋㅋㅋ: #N/A

Sheet 위험 알림
B2: 이지+천지 재고일수 45일 이하(위험)
A4: 자재코드 | B4: 자재내역 | C4: 3평판 | D4: SF | E4: 판매율(평판)% | F4: 판매율(SF)% | G4: 5000 | H4: 6090 | I4: 총재고 | J4: 이지+천지재고 | K4: 4월순매출수량 | L4: 재고대응률 | M4: 일평균소진 | N4: 이지+천지재고일수 | O4: 총재고일수 | P4: 품절예상일 | Q4: 위험도(일평균소진) | R4: 위험도(엑셀관리)
A5: 1000940 | B5: [원료]DW-EGFLiposol(EGF-나노리포좀)250ppm 1g | C5: 0 | D5: 0 | E5: 0 | F5: 0 | G5: 117800 | H5: 0 | I5: 584810.05 | J5: 117800 | K5: 0 | L5: 계획없음 | M5: 0 | O5: 일평균소진없음 | Q5: 데이터 없음 | R5: 판매없음
A6: 1300271 | B6: [원료]대웅제약_DW-EGF동결원액_4mg/1ml | C6: 0 | D6: 0 | E6: 0 | F6: 0 | G6: 0 | H6: 0 | I6: 1201.96 | J6: 0 | K6: 0 | L6: 계획없음 | M6: 0 | O6: 일평균소진없음 | Q6: 데이터 없음 | R6: 판매없음
A7: 2301915 | B7: (단종)[판촉물]쇼핑백_23년프로모션(245*95*230) | C7: 0 | D7: 0 | E7: 0 | F7: 0 | G7: 13 | H7: 0 | I7: 13 | J7: 13 | K7: 0 | L7: 계획없음 | M7: 0 | O7: 일평균소진없음 | Q7: 데이터 없음 | R7: 판매없음
A8: 2302226 | B8: [세트포장재_면세슬리브]멜라토닝패치4매*3박스 | C8: 0 | D8: 0 | E8: 0 | F8: 0 | G8: 2324 | H8: 0 | I8: 2324 | J8: 2324 | K8: 0 | L8: 계획없음 | M8: 0 | O8: 일평균소진없음 | Q8: 데이터 없음 | R8: 판매없음
A9: 2302396 | B9: (단종)[세트포장재_슬리브]멜라비타씨토너_한가인싸인(판촉몰) | C9: 0 | D9: 0 | E9: 0 | F9: 0 | G9: 13500 | H9: 0 | I9: 13500 | J9: 13500 | K9: 0 | L9: 계획없음 | M9: 0 | O9: 일평균소진없음 | Q9: 데이터 없음 | R9: 판매없음
A10: 2302427 | B10: (단종)[세트포장재_슬리브]기미앰플1ml+더마니들1구_한가인싸인(판촉몰) | C10: 0 | D10: 0 | E10: 0 | F10: 0 | G10: 17549 | H10: 0 | I10: 17549 | J10: 17549 | K10: 0 | L10: 계획없음 | M10: 0 | O10: 일평균소진없음 | Q10: 데이터 없음 | R10: 판매없음
A11: 2302428 | B11: (단종)[세트포장재]이지듀2024가정의달vIP싸바리_쇼핑백 | C11: 0 | D11: 0 | E11: 0 | F11: 0 | G11: 4 | H11: 0 | I11: 4 | J11: 4 | K11: 0 | L11: 계획없음 | M11: 0 | O11: 일평균소진없음 | Q11: 데이터 없음 | R11: 판매없음
A12: 2302436 | B12: (단종)[세트포장재]더마톡스니들롤러대_단상자 | C12: 0 | D12: 0 | E12: 0 | F12: 0 | G12: 5226 | H12: 0 | I12: 5226 | J12: 5226 | K12: 0 | L12: 계획없음 | M12: 0 | O12: 일평균소진없음 | Q12: 데이터 없음 | R12: 판매없음
A13: 2302564 | B13: (단종)[세트포장재]멜라_라필프로페셔널툴즈키트_단상자 | C13: 0 | D13: 0 | E13: 0 | F13: 0 | G13: 2000 | H13: 0 | I13: 2000 | J13: 2000 | K13: 0 | L13: 계획없음 | M13: 0 | O13: 일평균소진없음 | Q13: 데이터 없음 | R13: 판매없음
A14: 2302650 | B14: [세트포장재_싸바리박스]멜라3스텝_명절용스페셜세트 | C14: 0 | D14: 0 | E14: 0 | F14: 0 | G14: 303 | H14: 0 | I14: 303 | J14: 303 | K14: 0 | L14: 계획없음 | M14: 0 | O14: 일평균소진없음 | Q14: 데이터 없음 | R14: 판매없음
A15: 2302671 | B15: (단종)[세트포장재_슬리브]스킨부스터_나이아신앰플 | C15: 0 | D15: 0 | E15: 0 | F15: 0 | G15: 4029 | H15: 0 | I15: 4029 | J15: 4029 | K15: 0 | L15: 계획없음 | M15: 0 | O15: 일평균소진없음 | Q15: 데이터 없음 | R15: 판매없음
A16: 2302672 | B16: (단종)[세트포장재_슬리브]스킨부스터_피디알엔앰플 | C16: 0 | D16: 0 | E16: 0 | F16: 0 | G16: 4114 | H16: 0 | I16: 4114 | J16: 4114 | K16: 0 | L16: 계획없음 | M16: 0 | O16: 일평균소진없음 | Q16: 데이터 없음 | R16: 판매없음
... A24: 2302997 | B24: [판촉물_부자재]멜라토닝 VIP 고급 대관세트(2025)_리플렛 | C24: 0 | D24: 0 | E24: 0 | F24: 0 | G24: 185 | H24: 0 | I24: 185 | J24: 185 | K24: 0 | L24: 계획없음 | M24: 0 | O24: 일평균소진없음 | Q24: 데이터 없음 | R24: 판매없음
A25: 2303084 | B25: [EA]이지듀멜라비토닝미스트로즈쇼핑백 | C25: 0 | D25: 1023.4295 | E25: 0 | F25: 0 | G25: 6943 | H25: 0 | I25: 6949 | J25: 6943 | K25: 10 | L25: 6.7840533 | M25: 1.4285714 | N25: 4860.1 | O25: 4864.3 | P25: 2039-07-29 | Q25: 과재고 | R25: 안전
A26: 2303245 | B26: (단종)[세트포장재]앰플쿠션_19호_면세세트(본품+리필2)_단상자_v3 | C26: 0 | D26: 0 | E26: 0 | F26: 0 | G26: 705 | H26: 0 | I26: 705 | J26: 705 | K26: 0 | L26: 계획없음 | M26: 0 | O26: 일평균소진없음 | Q26: 데이터 없음 | R26: 판매없음
A27: 2303246 | B27: (단종)[세트포장재]앰플쿠션_21호_면세세트(본품+리필2)_단상자_v3 | C27: 0 | D27: 0 | E27: 0 | F27: 0 | G27: 1023 | H27: 0 | I27: 1023 | J27: 1023 | K27: 0 | L27: 계획없음 | M27: 0 | O27: 일평균소진없음 | Q27: 데이터 없음 | R27: 판매없음
A28: 2303247 | B28: (단종)[세트포장재]앰플쿠션_23호_면세세트(본품+리필2)_단상자_v3 | C28: 0 | D28: 0 | E28: 0 | F28: 0 | G28: 715 | H28: 0 | I28: 715 | J28: 715 | K28: 0 | L28: 계획없음 | M28: 0 | O28: 일평균소진없음 | Q28: 데이터 없음 | R28: 판매없음
A29: 2303248 | B29: 이지듀멜라비토닝원데이앰플로즈에디션_세트단상자(박스형) | C29: 0 | D29: 0 | E29: 0 | F29: 0 | G29: 14285 | H29: 0 | I29: 14385 | J29: 14285 | K29: 0 | L29: 계획없음 | M29: 0 | O29: 일평균소진없음 | Q29: 데이터 없음 | R29: 판매없음
A30: 2303273 | B30: (단종)[세트포장재]멜라B_선세럼_40ml더블기획(면세)_세트단상자 | C30: 0 | D30: 0 | E30: 0 | F30: 0 | G30: 1100 | H30: 0 | I30: 1100 | J30: 1100 | K30: 0 | L30: 계획없음 | M30: 0 | O30: 일평균소진없음 | Q30: 데이터 없음 | R30: 판매없음
A31: 2303293 | B31: (단종)[세트포장재]비타_앰플클렌저_200ml_단상자 | C31: 0 | D31: 0 | E31: 0 | F31: 0 | G31: 1100 | H31: 0 | I31: 1100 | J31: 1100 | K31: 0 | L31: 계획없음 | M31: 0 | O31: 일평균소진없음 | Q31: 데이터 없음 | R31: 판매없음
A32: 2303297 | B32: (단종)[세트포장재]클리어_에스오에스_스팟15ml_단상자 | C32: 0 | D32: 0 | E32: 0 | F32: 0 | G32: 4900 | H32: 0 | I32: 4900 | J32: 4900 | K32: 0 | L32: 계획없음 | M32: 0 | O32: 일평균소진없음 | Q32: 데이터 없음 | R32: 판매없음
A33: 2303299 | B33: (단종)[세트포장재]클리어_B3+B5세럼29ml_단상자 | C33: 0 | D33: 0 | E33: 0 | F33: 0 | G33: 4500 | H33: 0 | I33: 4500 | J33: 4500 | K33: 0 | L33: 계획없음 | M33: 0 | O33: 일평균소진없음 | Q33: 데이터 없음 | R33: 판매없음
A34: 2303300 | B34: (단종)[세트포장재]클리어_아하2%토너200ml_단상자 | C34: 0 | D34: 0 | E34: 0 | F34: 0 | G34: 1000 | H34: 0 | I34: 1000 | J34: 1000 | K34: 0 | L34: 계획없음 | M34: 0 | O34: 일평균소진없음 | Q34: 데이터 없음 | R34: 판매없음
A35: 2303301 | B35: (단종)[세트포장재]클리어_바하클렌저100ml_단상자 | C35: 0 | D35: 0 | E35: 0 | F35: 0 | G35: 1000 | H35: 0 | I35: 1000 | J35: 1000 | K35: 0 | L35: 계획없음 | M35: 0 | O35: 일평균소진없음 | Q35: 데이터 없음 | R35: 판매없음
A36: 2303302 | B36: (단종)[세트포장재]클리어_라하바디미스트100ml_단상자 | C36: 0 | D36: 0 | E36: 0 | F36: 0 | G36: 1000 | H36: 0 | I36: 1000 | J36: 1000 | K36: 0 | L36: 계획없음 | M36: 0 | O36: 일평균소진없음 | Q36: 데이터 없음 | R36: 판매없음
A37: 2303304 | B37: (단종)[세트포장재]클리어_바하바디클렌저300g_단상자 | C37: 0 | D37: 0 | E37: 0 | F37: 0 | G37: 1000 | H37: 0 | I37: 1000 | J37: 1000 | K37: 0 | L37: 계획없음 | M37: 0 | O37: 일평균소진없음 | Q37: 데이터 없음 | R37: 판매없음
... A93: 7001011 | B93: [판촉물_상품]실리콘클렌징브러쉬(비비또)_오렌지 | C93: 0 | D93: 0 | E93: 0 | F93: 0 | G93: 467 | H93: 0 | I93: 467 | J93: 467 | K93: 0 | L93: 계획없음 | M93: 0 | O93: 일평균소진없음 | Q93: 데이터 없음 | R93: 판매없음
A94: 7001012 | B94: [판촉물_상품]클렌징브러쉬듀오 | C94: 0 | D94: 0 | E94: 0 | F94: 0 | G94: 4245 | H94: 0 | I94: 4245 | J94: 4245 | K94: 6 | L94: 계획없음 | M94: 0.85714286 | N94: 4952.5 | O94: 4952.5 | P94: 2039-10-29 | Q94: 과재고 | R94: 안전
A95: 7001034 | B95: 페이스템C(0.8CC*2EA) | C95: 0 | D95: 0 | E95: 0 | F95: 0 | G95: 0 | H95: 0 | I95: 0 | J95: 0 | K95: 0 | L95: 계획없음 | M95: 0 | O95: 일평균소진없음 | Q95: 데이터 없음 | R95: 판매없음
A96: 7001039 | B96: 지젤리뉴유니버셜(1CC*2EA) | C96: 0 | D96: 0 | E96: 0 | F96: 0 | G96: 0 | H96: 0 | I96: 0 | J96: 0 | K96: 0 | L96: 계획없음 | M96: 0 | O96: 일평균소진없음 | Q96: 데이터 없음 | R96: 판매없음
A97: 7001042 | B97: 나보타주1VI*1EA(100U)-DNC | C97: 0 | D97: 0 | E97: 0 | F97: 0 | G97: 0 | H97: 0 | I97: 0 | J97: 0 | K97: 0 | L97: 계획없음 | M97: 0 | O97: 일평균소진없음 | Q97: 데이터 없음 | R97: 판매없음
A98: 7001045 | B98: 나보타주1V*1EA(150U)-DNC | C98: 0 | D98: 0 | E98: 0 | F98: 0 | G98: 0 | H98: 0 | I98: 0 | J98: 0 | K98: 0 | L98: 계획없음 | M98: 0 | O98: 일평균소진없음 | Q98: 데이터 없음 | R98: 판매없음
A99: 7001046 | B99: 나보타주1V*1EA(200U)-DNC | C99: 0 | D99: 0 | E99: 0 | F99: 0 | G99: 0 | H99: 0 | I99: 0 | J99: 0 | K99: 0 | L99: 계획없음 | M99: 0 | O99: 일평균소진없음 | Q99: 데이터 없음 | R99: 판매없음
A100: 7001047 | B100: 나보타주1V*1EA(50U)-DNC | C100: 0 | D100: 0 | E100: 0 | F100: 0 | G100: 0 | H100: 0 | I100: 0 | J100: 0 | K100: 0 | L100: 계획없음 | M100: 0 | O100: 일평균소진없음 | Q100: 데이터 없음 | R100: 판매없음
A101: 7300266 | B101: 이지덤뷰티 뷰티 42매 (파우치, 온라인) | C101: 0 | D101: 0 | E101: 0 | F101: 0 | G101: 0 | H101: 0 | I101: 0 | J101: 0 | K101: 0 | L101: 계획없음 | M101: 0 | O101: 일평균소진없음 | Q101: 데이터 없음 | R101: 판매없음
A102: 7300313 | B102: VOM V (1.0ml*2) | C102: 0 | D102: 0 | E102: 0 | F102: 0 | G102: 0 | H102: 0 | I102: 0 | J102: 0 | K102: 0 | L102: 계획없음 | M102: 0 | O102: 일평균소진없음 | Q102: 데이터 없음 | R102: 판매없음
A103: 7300314 | B103: VOM O (1.0ml*2) | C103: 0 | D103: 0 | E103: 0 | F103: 0 | G103: 0 | H103: 0 | I103: 0 | J103: 0 | K103: 0 | L103: 계획없음 | M103: 0 | O103: 일평균소진없음 | Q103: 데이터 없음 | R103: 판매없음
A104: 7300315 | B104: VOM M (1.0ml*2) | C104: 0 | D104: 0 | E104: 0 | F104: 0 | G104: 0 | H104: 0 | I104: 0 | J104: 0 | K104: 0 | L104: 계획없음 | M104: 0 | O104: 일평균소진없음 | Q104: 데이터 없음 | R104: 판매없음
...

Sheet RAW
B1: 자재코드 | C1: 자재내역 | D1: 3평판 | E1: SF | F1: 당월출하 | G1: 판매율(평판) | H1: 판매율(SF) | I1: 5000 | J1: 6090 | K1: 총재고 | L1: 이지+천지재고 | M1: 순매출수량 | N1: 재고대응률 | O1: 일평균소진 | P1: 이지+천지재고일수(일평균소진) | Q1: 이지+천지재고일수(3평판) | R1: 총재고일수 | S1: 품절예상일 | T1: 위험도(일평균소진) | U1: 위험도(3평판) | V1: 위험도(엑셀관리)
A2: 0 | B2: 1000940 | C2: [원료]DW-EGFLiposol(EGF-나노리포좀)250ppm 1g | D2: 0 | E2: 0 | F2: 0 | G2: 0 | H2: 0 | I2: 117800 | J2: 0 | K2: 584810.05 | L2: 117800 | M2: 0 | N2: 계획없음 | O2: 0 | R2: 일평균소진없음 | T2: 데이터 없음 | U2: 데이터 없음 | V2: 판매없음
A3: 1 | B3: 1300271 | C3: [원료]대웅제약_DW-EGF동결원액_4mg/1ml | D3: 0 | E3: 0 | F3: 0 | G3: 0 | H3: 0 | I3: 0 | J3: 0 | K3: 1201.96 | L3: 0 | M3: 0 | N3: 계획없음 | O3: 0 | R3: 일평균소진없음 | T3: 데이터 없음 | U3: 데이터 없음 | V3: 판매없음
A4: 2 | B4: 2301915 | C4: (단종)[판촉물]쇼핑백_23년프로모션(245*95*230) | D4: 0 | E4: 0 | F4: 0 | G4: 0 | H4: 0 | I4: 13 | J4: 0 | K4: 13 | L4: 13 | M4: 0 | N4: 계획없음 | O4: 0 | R4: 일평균소진없음 | T4: 데이터 없음 | U4: 데이터 없음 | V4: 판매없음
A5: 3 | B5: 2302226 | C5: [세트포장재_면세슬리브]멜라토닝패치4매*3박스 | D5: 0 | E5: 0 | F5: 0 | G5: 0 | H5: 0 | I5: 2324 | J5: 0 | K5: 2324 | L5: 2324 | M5: 0 | N5: 계획없음 | O5: 0 | R5: 일평균소진없음 | T5: 데이터 없음 | U5: 데이터 없음 | V5: 판매없음
A6: 4 | B6: 2302396 | C6: (단종)[세트포장재_슬리브]멜라비타씨토너_한가인싸인(판촉몰) | D6: 0 | E6: 0 | F6: 0 | G6: 0 | H6: 0 | I6: 13500 | J6: 0 | K6: 13500 | L6: 13500 | M6: 0 | N6: 계획없음 | O6: 0 | R6: 일평균소진없음 | T6: 데이터 없음 | U6: 데이터 없음 | V6: 판매없음
A7: 5 | B7: 2302427 | C7: (단종)[세트포장재_슬리브]기미앰플1ml+더마니들1구_한가인싸인(판촉몰) | D7: 0 | E7: 0 | F7: 0 | G7: 0 | H7: 0 | I7: 17549 | J7: 0 | K7: 17549 | L7: 17549 | M7: 0 | N7: 계획없음 | O7: 0 | R7: 일평균소진없음 | T7: 데이터 없음 | U7: 데이터 없음 | V7: 판매없음
A8: 6 | B8: 2302428 | C8: (단종)[세트포장재]이지듀2024가정의달vIP싸바리_쇼핑백 | D8: 0 | E8: 0 | F8: 0 | G8: 0 | H8: 0 | I8: 4 | J8: 0 | K8: 4 | L8: 4 | M8: 0 | N8: 계획없음 | O8: 0 | R8: 일평균소진없음 | T8: 데이터 없음 | U8: 데이터 없음 | V8: 판매없음
A9: 7 | B9: 2302436 | C9: (단종)[세트포장재]더마톡스니들롤러대_단상자 | D9: 0 | E9: 0 | F9: 0 | G9: 0 | H9: 0 | I9: 5226 | J9: 0 | K9: 5226 | L9: 5226 | M9: 0 | N9: 계획없음 | O9: 0 | R9: 일평균소진없음 | T9: 데이터 없음 | U9: 데이터 없음 | V9: 판매없음
A10: 8 | B10: 2302564 | C10: (단종)[세트포장재]멜라_라필프로페셔널툴즈키트_단상자 | D10: 0 | E10: 0 | F10: 0 | G10: 0 | H10: 0 | I10: 2000 | J10: 0 | K10: 2000 | L10: 2000 | M10: 0 | N10: 계획없음 | O10: 0 | R10: 일평균소진없음 | T10: 데이터 없음 | U10: 데이터 없음 | V10: 판매없음
A11: 9 | B11: 2302650 | C11: [세트포장재_싸바리박스]멜라3스텝_명절용스페셜세트 | D11: 0 | E11: 0 | F11: 0 | G11: 0 | H11: 0 | I11: 303 | J11: 0 | K11: 303 | L11: 303 | M11: 0 | N11: 계획없음 | O11: 0 | R11: 일평균소진없음 | T11: 데이터 없음 | U11: 데이터 없음 | V11: 판매없음
A12: 10 | B12: 2302671 | C12: (단종)[세트포장재_슬리브]스킨부스터_나이아신앰플 | D12: 0 | E12: 0 | F12: 0 | G12: 0 | H12: 0 | I12: 4029 | J12: 0 | K12: 4029 | L12: 4029 | M12: 0 | N12: 계획없음 | O12: 0 | R12: 일평균소진없음 | T12: 데이터 없음 | U12: 데이터 없음 | V12: 판매없음
A13: 11 | B13: 2302672 | C13: (단종)[세트포장재_슬리브]스킨부스터_피디알엔앰플 | D13: 0 | E13: 0 | F13: 0 | G13: 0 | H13: 0 | I13: 4114 | J13: 0 | K13: 4114 | L13: 4114 | M13: 0 | N13: 계획없음 | O13: 0 | R13: 일평균소진없음 | T13: 데이터 없음 | U13: 데이터 없음 | V13: 판매없음
... A21: 19 | B21: 2302997 | C21: [판촉물_부자재]멜라토닝 VIP 고급 대관세트(2025)_리플렛 | D21: 0 | E21: 0 | F21: 0 | G21: 0 | H21: 0 | I21: 185 | J21: 0 | K21: 185 | L21: 185 | M21: 0 | N21: 계획없음 | O21: 0 | R21: 일평균소진없음 | T21: 데이터 없음 | U21: 데이터 없음 | V21: 판매없음
A22: 20 | B22: 2303084 | C22: [EA]이지듀멜라비토닝미스트로즈쇼핑백 | D22: 0 | E22: 1023.4295 | F22: 0 | G22: 0 | H22: 0 | I22: 6943 | J22: 0 | K22: 6949 | L22: 6943 | M22: 10 | N22: 6.7840533 | O22: 1.4285714 | P22: 4860.1 | R22: 4864.3 | S22: 2039-07-29 | T22: 과재고 | U22: 데이터 없음 | V22: 안전
A23: 21 | B23: 2303245 | C23: (단종)[세트포장재]앰플쿠션_19호_면세세트(본품+리필2)_단상자_v3 | D23: 0 | E23: 0 | F23: 0 | G23: 0 | H23: 0 | I23: 705 | J23: 0 | K23: 705 | L23: 705 | M23: 0 | N23: 계획없음 | O23: 0 | R23: 일평균소진없음 | T23: 데이터 없음 | U23: 데이터 없음 | V23: 판매없음
A24: 22 | B24: 2303246 | C24: (단종)[세트포장재]앰플쿠션_21호_면세세트(본품+리필2)_단상자_v3 | D24: 0 | E24: 0 | F24: 0 | G24: 0 | H24: 0 | I24: 1023 | J24: 0 | K24: 1023 | L24: 1023 | M24: 0 | N24: 계획없음 | O24: 0 | R24: 일평균소진없음 | T24: 데이터 없음 | U24: 데이터 없음 | V24: 판매없음
A25: 23 | B25: 2303247 | C25: (단종)[세트포장재]앰플쿠션_23호_면세세트(본품+리필2)_단상자_v3 | D25: 0 | E25: 0 | F25: 0 | G25: 0 | H25: 0 | I25: 715 | J25: 0 | K25: 715 | L25: 715 | M25: 0 | N25: 계획없음 | O25: 0 | R25: 일평균소진없음 | T25: 데이터 없음 | U25: 데이터 없음 | V25: 판매없음
A26: 24 | B26: 2303248 | C26: 이지듀멜라비토닝원데이앰플로즈에디션_세트단상자(박스형) | D26: 0 | E26: 0 | F26: 0 | G26: 0 | H26: 0 | I26: 14285 | J26: 0 | K26: 14385 | L26: 14285 | M26: 0 | N26: 계획없음 | O26: 0 | R26: 일평균소진없음 | T26: 데이터 없음 | U26: 데이터 없음 | V26: 판매없음
A27: 25 | B27: 2303273 | C27: (단종)[세트포장재]멜라B_선세럼_40ml더블기획(면세)_세트단상자 | D27: 0 | E27: 0 | F27: 0 | G27: 0 | H27: 0 | I27: 1100 | J27: 0 | K27: 1100 | L27: 1100 | M27: 0 | N27: 계획없음 | O27: 0 | R27: 일평균소진없음 | T27: 데이터 없음 | U27: 데이터 없음 | V27: 판매없음
A28: 26 | B28: 2303293 | C28: (단종)[세트포장재]비타_앰플클렌저_200ml_단상자 | D28: 0 | E28: 0 | F28: 0 | G28: 0 | H28: 0 | I28: 1100 | J28: 0 | K28: 1100 | L28: 1100 | M28: 0 | N28: 계획없음 | O28: 0 | R28: 일평균소진없음 | T28: 데이터 없음 | U28: 데이터 없음 | V28: 판매없음
A29: 27 | B29: 2303297 | C29: (단종)[세트포장재]클리어_에스오에스_스팟15ml_단상자 | D29: 0 | E29: 0 | F29: 0 | G29: 0 | H29: 0 | I29: 4900 | J29: 0 | K29: 4900 | L29: 4900 | M29: 0 | N29: 계획없음 | O29: 0 | R29: 일평균소진없음 | T29: 데이터 없음 | U29: 데이터 없음 | V29: 판매없음
A30: 28 | B30: 2303299 | C30: (단종)[세트포장재]클리어_B3+B5세럼29ml_단상자 | D30: 0 | E30: 0 | F30: 0 | G30: 0 | H30: 0 | I30: 4500 | J30: 0 | K30: 4500 | L30: 4500 | M30: 0 | N30: 계획없음 | O30: 0 | R30: 일평균소진없음 | T30: 데이터 없음 | U30: 데이터 없음 | V30: 판매없음
A31: 29 | B31: 2303300 | C31: (단종)[세트포장재]클리어_아하2%토너200ml_단상자 | D31: 0 | E31: 0 | F31: 0 | G31: 0 | H31: 0 | I31: 1000 | J31: 0 | K31: 1000 | L31: 1000 | M31: 0 | N31: 계획없음 | O31: 0 | R31: 일평균소진없음 | T31: 데이터 없음 | U31: 데이터 없음 | V31: 판매없음
A32: 30 | B32: 2303301 | C32: (단종)[세트포장재]클리어_바하클렌저100ml_단상자 | D32: 0 | E32: 0 | F32: 0 | G32: 0 | H32: 0 | I32: 1000 | J32: 0 | K32: 1000 | L32: 1000 | M32: 0 | N32: 계획없음 | O32: 0 | R32: 일평균소진없음 | T32: 데이터 없음 | U32: 데이터 없음 | V32: 판매없음
A33: 31 | B33: 2303302 | C33: (단종)[세트포장재]클리어_라하바디미스트100ml_단상자 | D33: 0 | E33: 0 | F33: 0 | G33: 0 | H33: 0 | I33: 1000 | J33: 0 | K33: 1000 | L33: 1000 | M33: 0 | N33: 계획없음 | O33: 0 | R33: 일평균소진없음 | T33: 데이터 없음 | U33: 데이터 없음 | V33: 판매없음
A34: 32 | B34: 2303304 | C34: (단종)[세트포장재]클리어_바하바디클렌저300g_단상자 | D34: 0 | E34: 0 | F34: 0 | G34: 0 | H34: 0 | I34: 1000 | J34: 0 | K34: 1000 | L34: 1000 | M34: 0 | N34: 계획없음 | O34: 0 | R34: 일평균소진없음 | T34: 데이터 없음 | U34: 데이터 없음 | V34: 판매없음
... A90: 88 | B90: 7001011 | C90: [판촉물_상품]실리콘클렌징브러쉬(비비또)_오렌지 | D90: 0 | E90: 0 | F90: 0 | G90: 0 | H90: 0 | I90: 467 | J90: 0 | K90: 467 | L90: 467 | M90: 0 | N90: 계획없음 | O90: 0 | R90: 일평균소진없음 | T90: 데이터 없음 | U90: 데이터 없음 | V90: 판매없음
A91: 89 | B91: 7001012 | C91: [판촉물_상품]클렌징브러쉬듀오 | D91: 0 | E91: 0 | F91: 0 | G91: 0 | H91: 0 | I91: 4245 | J91: 0 | K91: 4245 | L91: 4245 | M91: 6 | N91: 계획없음 | O91: 0.85714286 | P91: 4952.5 | R91: 4952.5 | S91: 2039-10-29 | T91: 과재고 | U91: 데이터 없음 | V91: 안전
A92: 90 | B92: 7001034 | C92: 페이스템C(0.8CC*2EA) | D92: 0 | E92: 0 | F92: 0 | G92: 0 | H92: 0 | I92: 0 | J92: 0 | K92: 0 | L92: 0 | M92: 0 | N92: 계획없음 | O92: 0 | R92: 일평균소진없음 | T92: 데이터 없음 | U92: 데이터 없음 | V92: 판매없음
A93: 91 | B93: 7001039 | C93: 지젤리뉴유니버셜(1CC*2EA) | D93: 0 | E93: 0 | F93: 0 | G93: 0 | H93: 0 | I93: 0 | J93: 0 | K93: 0 | L93: 0 | M93: 0 | N93: 계획없음 | O93: 0 | R93: 일평균소진없음 | T93: 데이터 없음 | U93: 데이터 없음 | V93: 판매없음
A94: 92 | B94: 7001042 | C94: 나보타주1VI*1EA(100U)-DNC | D94: 0 | E94: 0 | F94: 0 | G94: 0 | H94: 0 | I94: 0 | J94: 0 | K94: 0 | L94: 0 | M94: 0 | N94: 계획없음 | O94: 0 | R94: 일평균소진없음 | T94: 데이터 없음 | U94: 데이터 없음 | V94: 판매없음
A95: 93 | B95: 7001045 | C95: 나보타주1V*1EA(150U)-DNC | D95: 0 | E95: 0 | F95: 0 | G95: 0 | H95: 0 | I95: 0 | J95: 0 | K95: 0 | L95: 0 | M95: 0 | N95: 계획없음 | O95: 0 | R95: 일평균소진없음 | T95: 데이터 없음 | U95: 데이터 없음 | V95: 판매없음
A96: 94 | B96: 7001046 | C96: 나보타주1V*1EA(200U)-DNC | D96: 0 | E96: 0 | F96: 0 | G96: 0 | H96: 0 | I96: 0 | J96: 0 | K96: 0 | L96: 0 | M96: 0 | N96: 계획없음 | O96: 0 | R96: 일평균소진없음 | T96: 데이터 없음 | U96: 데이터 없음 | V96: 판매없음
A97: 95 | B97: 7001047 | C97: 나보타주1V*1EA(50U)-DNC | D97: 0 | E97: 0 | F97: 0 | G97: 0 | H97: 0 | I97: 0 | J97: 0 | K97: 0 | L97: 0 | M97: 0 | N97: 계획없음 | O97: 0 | R97: 일평균소진없음 | T97: 데이터 없음 | U97: 데이터 없음 | V97: 판매없음
A98: 96 | B98: 7300266 | C98: 이지덤뷰티 뷰티 42매 (파우치, 온라인) | D98: 0 | E98: 0 | F98: 0 | G98: 0 | H98: 0 | I98: 0 | J98: 0 | K98: 0 | L98: 0 | M98: 0 | N98: 계획없음 | O98: 0 | R98: 일평균소진없음 | T98: 데이터 없음 | U98: 데이터 없음 | V98: 판매없음
A99: 97 | B99: 7300313 | C99: VOM V (1.0ml*2) | D99: 0 | E99: 0 | F99: 0 | G99: 0 | H99: 0 | I99: 0 | J99: 0 | K99: 0 | L99: 0 | M99: 0 | N99: 계획없음 | O99: 0 | R99: 일평균소진없음 | T99: 데이터 없음 | U99: 데이터 없음 | V99: 판매없음
A100: 98 | B100: 7300314 | C100: VOM O (1.0ml*2) | D100: 0 | E100: 0 | F100: 0 | G100: 0 | H100: 0 | I100: 0 | J100: 0 | K100: 0 | L100: 0 | M100: 0 | N100: 계획없음 | O100: 0 | R100: 일평균소진없음 | T100: 데이터 없음 | U100: 데이터 없음 | V100: 판매없음
A101: 99 | B101: 7300315 | C101: VOM M (1.0ml*2) | D101: 0 | E101: 0 | F101: 0 | G101: 0 | H101: 0 | I101: 0 | J101: 0 | K101: 0 | L101: 0 | M101: 0 | N101: 계획없음 | O101: 0 | R101: 일평균소진없음 | T101: 데이터 없음 | U101: 데이터 없음 | V101: 판매없음
A102: 100 | B102: 7300398 | C102: 지젤리뉴시그니처1(1CC*2EA) | D102: 0 | E102: 0 | F102: 0 | G102: 0 | H102: 0 | I102: 0 | J102: 0 | K102: 0 | L102: 0 | M102: 0 | N102: 계획없음 | O102: 0 | R102: 일평균소진없음 | T102: 데이터 없음 | U102: 데이터 없음 | V102: 판매없음
...

Sheet 모니터링
K1: 월 기초일자(4월) | L1: 월 기말일자(4월) | M1: 경과일 | N1: 월 기간 | O1: 잔여일
K2: 46113 | L2: 46142 | M2: =DATEDIF(K2,TODAY(),"d") -> 7 | N2: =DATEDIF(K2,L2,"d") -> 29 | O2: =N2-M2 -> 22 | X2: 입고일수 및 남은 일수 수정필요
A3: ㅇ | B3: 제조사코드 | D3: 1 | E3: 2 | F3: 3 | G3: 4 | H3: 5 | I3: 6 | J3: 7 | K3: 8 | L3: 9 | M3: 10 | N3: 11 | O3: 12 | P3: 13 | Q3: 14 | R3: 15 | S3: 16 | T3: 17 | U3: 18 | V3: 19 | W3: 20 | X3: 21 | Y3: 22 | Z3: 23 | AA3: 24 | AB3: 25 | AC3: 26 | AD3: 27 | AE3: 28 | AF3: 29 | AG3: 30 | AH3: 31 | AI3: 32 | AJ3: 33 | AK3: 34 | AL3: 35 | AM3: 36 | AN3: 37 | AO3: 38 | AP3: 39 | AQ3: 40 | AR3: 41 | AS3: 42 | AT3: 43 | AU3: 44 | AV3: 45 | FL3: 0
A4: 대표품목 (대표품목 6개월) | B4: 품목구분 | C4: 구분 | D4: 수량(3월) | E4: 품목 | F4: 제조사 | G4: 포장재 | H4: 비고 | I4: 원가 | J4: 판가 | K4: =TODAY() -> 46120 | O4: 모니터링파일 | V4: 4월 | AC4: 3월 | AH4: 4월 | AM4: 5월 | AR4: 6월
K5: 5000 | L5: 6090 | M5: 오산+천지 재고 | N5: Total 재고 | O5: 재고 대응률 | P5: 입고수량 | Q5: 일평균소진 | R5: 오산+천지(일) | S5: TOTAL (일) | T5: 품절예상일 | U5: 위험도 | V5: 영업 FCST | W5: act. | X5: remaine | Y5: 생산 | Z5: 생산비고 | AA5: 기말재고 | AB5: 재고대응률 | AC5: 영업 FCST | AD5: 입고 | AE5: 생산비고 | AF5: 기말재고 | AG5: 재고대응률 | AH5: 영업 FCST | AI5: 입고 | AJ5: 생산비고 | AK5: 기말재고 | AL5: 재고대응률 | AM5: 영업 FCST | AN5: 입고 | AO5: 생산비고 | AP5: 기말재고 | AQ5: 재고대응률 | AR5: 영업 FCST | AS5: 입고 | AT5: 생산비고 | AU5: 기말재고 | AV5: 재고대응률
K6: 이지메디컴 | L6: 천지로지스 | V6: 4월취합 | W6: sales(판매현황) | X6: sales(잔여예측) | AC6: 3월취합 | AD6: 3월 | AH6: 3월취합 | AI6: 4월 | AM6: 5월 취합 | AN6: 5월 | AR6: 6월 FCST | AS6: 6월
K7: =SUBTOTAL(9,K8:K1048576) -> 74597 | L7: =SUBTOTAL(9,L8:L1048576) -> 181449 | M7: =SUBTOTAL(9,M8:M1048576) -> 256046 | N7: =SUBTOTAL(9,N8:N1048576) -> 370238 | V7: =SUM(V8:V583) -> 826953.83 | W7: =SUBTOTAL(9,W8:W770) -> 110944 | X7: =SUM(X8:X583) -> 535329.14 | Y7: =SUM(Y8:Y583) -> 0 | AA7: =SUM(AA8:AA583) -> 4673358.9 | AC7: =SUM(AC8:AC583) -> 900200 | AD7: =SUBTOTAL(9,AD8:AD1048576) -> 129100 | AE7: =SUM(AE8:AE583) -> 0 | AF7: =SUM(AF8:AF583) -> 4668733.7 | AH7: =SUM(AH8:AH583) -> 826709.47 | AI7: =SUBTOTAL(9,AI8:AI1048576) -> 210000 | AJ7: =SUM(AJ8:AJ583) -> 17.160812 | AK7: =SUM(AK8:AK583) -> 4795555.8 | AM7: =SUM(AM8:AM583) -> 899884.74 | AN7: =SUBTOTAL(9,AN8:AN1048576) -> 0 | AO7: =SUM(AO8:AO583) -> 1298 | AP7: =SUM(AP8:AP583) -> 4289032.2 | AR7: =SUM(AR8:AR583) -> 1010427.7 | AS7: =SUBTOTAL(9,AS8:AS1048576) -> 0 | AT7: =SUM(AT8:AT583) -> 0 | AU7: =SUM(AU8:AU583) -> 3776157
A8: - | B8: 제품 | C8: 운영 | D8: 9309511 | E8: =VLOOKUP($D8,'[1]SAP 코드내역'!$A:$D,4,0) -> (단종)멜라_글루타치온크림_50ml(일본) | F8: 코스맥스(주) | I8: 2641.85 | J8: 13453.902 | K8: =IFERROR(VLOOKUP($D8,'[1]DNC 재고 현황'!$F:$AI,29,0),0) -> 0 | L8: =IFERROR(VLOOKUP($D8,'[1]DNC 재고 현황'!$F:$AI,30,),0) -> 0 | M8: =K8+L8 -> 0 | N8: =VLOOKUP($D8,'[1]DNC 재고 현황'!$F:$X,19,0) -> 4249 | O8: =IFERROR(IF($M8/$V8>1,100%,IF($M8/$V8<0,0%,$M8/$V8)),"계획없음") -> 0 | P8: =$Y8+$AD8+$AI8+$AN8+$AI8 -> 0 | Q8: =IFERROR(W8/$M$2,0) -> 0 | R8: =IFERROR(M8/$Q8,0) -> 0 | S8: =IFERROR(N8/$Q8,0) -> 0 | T8: =IFERROR(TODAY()+(M8/Q8),"") | U8: =IF(S8<=1,"🔴판매없음",IF(S8<=40,"🟡주의",IF(S8<=60,"🟢안전","✅충분"))) -> 🔴판매없음 | V8: =IFERROR(SUMIF('[1](전체)FCST'!$D:$D,$D8,'[1](전체)FCST'!$H:$H),0) -> 50 | W8: =IFERROR(VLOOKUP($D8,'[1]판매량,재고(피벗)'!$B:$C,2,0),0) -> 0 | X8: =IFERROR(W8/$M$2*$O$2,0) -> 0 | AA8: =MAX(SUM(N8-X8+Y8),0) -> 4249 | AB8: =IFERROR(AA8/AC8,0) -> 0.8498 | AC8: =IFERROR(VLOOKUP($D8,'[1]DNC 재고 현황'!$F:$V,14,0),0) -> 5000 | AD8: =SUMIFS('[1]입고 예정'!$C:$C,'[1]입고 예정'!$A:$A,모니터링!D8,'[1]입고 예정'!$F:$F,모니터링!AD$6) -> 0 | AF8: =MAX(IFERROR(SUM((AA8-AC8)+AD8),0),0) -> 0 | AG8: =IFERROR(AF8/AH8,0) -> 0 | AH8: =IFERROR(VLOOKUP($D8,'[1]DNC 재고 현황'!$F:$V,15,0),0) -> 50 | AI8: =SUMIFS('[1]입고 예정'!$C:$C,'[1]입고 예정'!$A:$A,모니터링!D8,'[1]입고 예정'!$F:$F,모니터링!AI$6) -> 0 | AK8: =MAX(IFERROR(SUM((AF8-AH8)+AI8),0),0) -> 0 | AL8: =IFERROR(AK8/AM8,0) -> 0 | AM8: =IFERROR(VLOOKUP($D8,'[1]DNC 재고 현황'!$F:$V,16,0),0) -> 50 | AN8: =SUMIFS('[1]입고 예정'!$C:$C,'[1]입고 예정'!$A:$A,모니터링!D8,'[1]입고 예정'!$F:$F,모니터링!AN$6) -> 0 | AP8: =MAX(IFERROR(SUM((AK8-AM8)+AN8),0),0) -> 0 | AQ8: =IFERROR(AP8/AR8,0) -> 0 | AR8: =IFERROR(VLOOKUP($D8,'[1]DNC 재고 현황'!$F:$V,17,0),0) -> 500 | AS8: =SUMIFS('[1]입고 예정'!$C:$C,'[1]입고 예정'!$A:$A,모니터링!D8,'[1]입고 예정'!$F:$F,모니터링!AS$6) -> 0 | AU8: =MAX(IFERROR(AP8-AR8+AS8,0),0) -> 0 | AV8: =IFERROR(AU8/#REF!,0) -> 0
A9: - | B9: 제품 | C9: 소진후 단종 | D9: 9307222 | E9: =VLOOKUP($D9,'[1]SAP 코드내역'!$A:$D,4,0) -> (단종)DWEGF_원데이10ppm_엠티에스2700샷(4ea)_스몰랩 | F9: ㈜스몰렙 | I9: 7960 | J9: 0 | K9: =IFERROR(VLOOKUP($D9,'[1]DNC 재고 현황'!$F:$AI,29,0),0) -> 91 | L9: =IFERROR(VLOOKUP($D9,'[1]DNC 재고 현황'!$F:$AI,30,),0) -> 0 | M9: =K9+L9 -> 91 | N9: =VLOOKUP($D9,'[1]DNC 재고 현황'!$F:$X,19,0) -> 91 | O9: =IFERROR(IF($M9/$V9>1,100%,IF($M9/$V9<0,0%,$M9/$V9)),"계획없음") -> 계획없음 | P9: =$Y9+$AD9+$AI9+$AN9+$AI9 -> 0 | Q9: =IFERROR(W9/$M$2,0) -> 0.14285714 | R9: =IFERROR(M9/$Q9,0) -> 637 | S9: =IFERROR(N9/$Q9,0) -> 637 | T9: =IFERROR(TODAY()+(M9/Q9),"") -> 46757 | U9: =IF(S9<=1,"🔴판매없음",IF(S9<=40,"🟡주의",IF(S9<=60,"🟢안전","✅충분"))) -> ✅충분 | V9: =IFERROR(SUMIF('[1](전체)FCST'!$D:$D,$D9,'[1](전체)FCST'!$H:$H),0) -> 0 | W9: =IFERROR(VLOOKUP($D9,'[1]판매량,재고(피벗)'!$B:$C,2,0),0) -> 1 | X9: =IFERROR(W9/$M$2*$O$2,0) -> 3.1428571 | AA9: =MAX(SUM(N9-X9+Y9),0) -> 87.857143 | AB9: =IFERROR(AA9/AC9,0) -> 0 | AC9: =IFERROR(VLOOKUP($D9,'[1]DNC 재고 현황'!$F:$V,14,0),0) -> 0 | AD9: =SUMIFS('[1]입고 예정'!$C:$C,'[1]입고 예정'!$A:$A,모니터링!D379,'[1]입고 예정'!$F:$F,모니터링!AD$6) -> 0 | AF9: =MAX(IFERROR(SUM((AA9-AC9)+AD9),0),0) -> 87.857143 | AG9: =IFERROR(AF9/AH9,0) -> 0 | AH9: =IFERROR(VLOOKUP($D9,'[1]DNC 재고 현황'!$F:$V,15,0),0) -> 0 | AI9: =SUMIFS('[1]입고 예정'!$C:$C,'[1]입고 예정'!$A:$A,모니터링!D379,'[1]입고 예정'!$F:$F,모니터링!AI$6) -> 0 | AK9: =MAX(IFERROR(SUM((AF9-AH9)+AI9),0),0) -> 87.857143 | AL9: =IFERROR(AK9/AM9,0) -> 0 | AM9: =IFERROR(VLOOKUP($D9,'[1]DNC 재고 현황'!$F:$V,16,0),0) -> 0 | AN9: =SUMIFS('[1]입고 예정'!$C:$C,'[1]입고 예정'!$A:$A,모니터링!D379,'[1]입고 예정'!$F:$F,모니터링!AN$6) -> 0 | AP9: =MAX(IFERROR(SUM((AK9-AM9)+AN9),0),0) -> 87.857143 | AQ9: =IFERROR(AP9/AR9,0) -> 0 | AR9: =IFERROR(VLOOKUP($D9,'[1]DNC 재고 현황'!$F:$V,17,0),0) -> 0 | AS9: =SUMIFS('[1]입고 예정'!$C:$C,'[1]입고 예정'!$A:$A,모니터링!D379,'[1]입고 예정'!$F:$F,모니터링!AS$6) -> 0 | AU9: =MAX(IFERROR(AP9-AR9+AS9,0),0) -> 87.857143 | AV9: =IFERROR(AU9/#REF!,0) -> 0
A10: - | B10: 판촉물 | C10: 운영 | D10: 7301041 | E10: =VLOOKUP($D10,'[1]SAP 코드내역'!$A:$D,4,0) -> [임가공]DWEGF_니들롤러대(단상자없음) | F10: 주식회사대웅이엔지 | I10: 1379.2833 | J10: 2908.5179 | K10: =IFERROR(VLOOKUP($D10,'[1]DNC 재고 현황'!$F:$AI,29,0),0) -> 0 | L10: =IFERROR(VLOOKUP($D10,'[1]DNC 재고 현황'!$F:$AI,30,),0) -> 0 | M10: =K10+L10 -> 0 | N10: =VLOOKUP($D10,'[1]DNC 재고 현황'!$F:$X,19,0) -> 7031 | O10: =IFERROR(IF($M10/$V10>1,100%,IF($M10/$V10<0,0%,$M10/$V10)),"계획없음") -> 계획없음 | P10: =$Y10+$AD10+$AI10+$AN10+$AI10 -> 0 | Q10: =IFERROR(W10/$M$2,0) -> 0 | R10: =IFERROR(M10/$Q10,0) -> 0 | S10: =IFERROR(N10/$Q10,0) -> 0 | T10: =IFERROR(TODAY()+(M10/Q10),"") | U10: =IF(S10<=1,"🔴판매없음",IF(S10<=40,"🟡주의",IF(S10<=60,"🟢안전","✅충분"))) -> 🔴판매없음 | V10: =IFERROR(SUMIF('[1](전체)FCST'!$D:$D,$D10,'[1](전체)FCST'!$H:$H),0) -> 0 | W10: =IFERROR(VLOOKUP($D10,'[1]판매량,재고(피벗)'!$B:$C,2,0),0) -> 0 | X10: =IFERROR(W10/$M$2*$O$2,0) -> 0 | AA10: =MAX(SUM(N10-X10+Y10),0) -> 7031 | AB10: =IFERROR(AA10/AC10,0) -> 0 | AC10: =IFERROR(VLOOKUP($D10,'[1]DNC 재고 현황'!$F:$V,14,0),0) -> 0 | AD10: =SUMIFS('[1]입고 예정'!$C:$C,'[1]입고 예정'!$A:$A,모니터링!D10,'[1]입고 예정'!$F:$F,모니터링!AD$6) -> 0 | AF10: =MAX(IFERROR(SUM((AA10-AC10)+AD10),0),0) -> 7031 | AG10: =IFERROR(AF10/AH10,0) -> 0 | AH10: =IFERROR(VLOOKUP($D10,'[1]DNC 재고 현황'!$F:$V,15,0),0) -> 0 | AI10: =SUMIFS('[1]입고 예정'!$C:$C,'[1]입고 예정'!$A:$A,모니터링!D10,'[1]입고 예정'!$F:$F,모니터링!AI$6) -> 0 | AK10: =MAX(IFERROR(SUM((AF10-AH10)+AI10),0),0) -> 7031 | AL10: =IFERROR(AK10/AM10,0) -> 0 | AM10: =IFERROR(VLOOKUP($D10,'[1]DNC 재고 현황'!$F:$V,16,0),0) -> 0 | AN10: =SUMIFS('[1]입고 예정'!$C:$C,'[1]입고 예정'!$A:$A,모니터링!D10,'[1]입고 예정'!$F:$F,모니터링!AN$6) -> 0 | AP10: =MAX(IFERROR(SUM((AK10-AM10)+AN10),0),0) -> 7031 | AQ10: =IFERROR(AP10/AR10,0) -> 0 | AR10: =IFERROR(VLOOKUP($D10,'[1]DNC 재고 현황'!$F:$V,17,0),0) -> 0 | AS10: =SUMIFS('[1]입고 예정'!$C:$C,'[1]입고 예정'!$A:$A,모니터링!D10,'[1]입고 예정'!$F:$F,모니터링!AS$6) -> 0 | AU10: =MAX(IFERROR(AP10-AR10+AS10,0),0) -> 7031 | AV10: =IFERROR(AU10/#REF!,0) -> 0
A11: - | B11: 제품 | C11: 운영 | D11: 9309401 | E11: =VLOOKUP($D11,'[1]SAP 코드내역'!$A:$D,4,0) -> 멜라B_토닝원데이앰플_2X_13ml*2+1ml*2(코스트코) | F11: 코스맥스(주) | I11: 7621.6442 | J11: 47447.273 | K11: =IFERROR(VLOOKUP($D11,'[1]DNC 재고 현황'!$F:$AI,29,0),0) -> 0 | L11: =IFERROR(VLOOKUP($D11,'[1]DNC 재고 현황'!$F:$AI,30,),0) -> 0 | M11: =K11+L11 -> 0 | N11: =VLOOKUP($D11,'[1]DNC 재고 현황'!$F:$X,19,0) -> 6998 | O11: =IFERROR(IF($M11/$V11>1,100%,IF($M11/$V11<0,0%,$M11/$V11)),"계획없음") -> 0 | P11: =$Y11+$AD11+$AI11+$AN11+$AI11 -> 10000 | Q11: =IFERROR(W11/$M$2,0) -> 0 | R11: =IFERROR(M11/$Q11,0) -> 0 | S11: =IFERROR(N11/$Q11,0) -> 0 | T11: =IFERROR(TODAY()+(M11/Q11),"") | U11: =IF(S11<=1,"🔴판매없음",IF(S11<=40,"🟡주의",IF(S11<=60,"🟢안전","✅충분"))) -> 🔴판매없음 | V11: =IFERROR(SUMIF('[1](전체)FCST'!$D:$D,$D11,'[1](전체)FCST'!$H:$H),0) -> 3688.2871 | W11: =IFERROR(VLOOKUP($D11,'[1]판매량,재고(피벗)'!$B:$C,2,0),0) -> 0 | X11: =IFERROR(W11/$M$2*$O$2,0) -> 0 | AA11: =MAX(SUM(N11-X11+Y11),0) -> 6998 | AB11: =IFERROR(AA11/AC11,0) -> 1.8973577 | AC11: =IFERROR(VLOOKUP($D11,'[1]DNC 재고 현황'!$F:$V,14,0),0) -> 3688.2871 | AD11: =SUMIFS('[1]입고 예정'!$C:$C,'[1]입고 예정'!$A:$A,모니터링!D11,'[1]입고 예정'!$F:$F,모니터링!AD$6) -> 10000 | AF11: =MAX(IFERROR(SUM((AA11-AC11)+AD11),0),0) -> 13309.713 | AG11: =IFERROR(AF11/AH11,0) -> 3.6086435 | AH11: =IFERROR(VLOOKUP($D11,'[1]DNC 재고 현황'!$F:$V,15,0),0) -> 3688.2871 | AI11: =SUMIFS('[1]입고 예정'!$C:$C,'[1]입고 예정'!$A:$A,모니터링!D11,'[1]입고 예정'!$F:$F,모니터링!AI$6) -> 0 | AK11: =MAX(IFERROR(SUM((AF11-AH11)+AI11),0),0) -> 9621.4259 | AL11: =IFERROR(AK11/AM11,0) -> 1.4802194 | AM11: =IFERROR(VLOOKUP($D11,'[1]DNC 재고 현황'!$F:$V,16,0),0) -> 6500 | AN11: =SUMIFS('[1]입고 예정'!$C:$C,'[1]입고 예정'!$A:$A,모니터링!D11,'[1]입고 예정'!$F:$F,모니터링!AN$6) -> 0 | AP11: =MAX(IFERROR(SUM((AK11-AM11)+AN11),0),0) -> 3121.4259 | AQ11: =IFERROR(AP11/AR11,0) -> 0.48021937 | AR11: =IFERROR(VLOOKUP($D11,'[1]DNC 재고 현황'!$F:$V,17,0),0) -> 6500 | AS11: =SUMIFS('[1]입고 예정'!$C:$C,'[1]입고 예정'!$A:$A,모니터링!D11,'[1]입고 예정'!$F:$F,모니터링!AS$6) -> 0 | AU11: =MAX(IFERROR(AP11-AR11+AS11,0),0) -> 0 | AV11: =IFERROR(AU11/#REF!,0) -> 0
B12: 완제품 | C12: 운영 | D12: 9313807 | E12: =VLOOKUP($D12,'[1]SAP 코드내역'!$A:$D,4,0) -> PDRN_18토닝세럼_마스크_120g*7매입(JP) | H12: 26년 신제품 | I12: 0 | J12: 0 | K12: =IFERROR(VLOOKUP($D12,'[1]DNC 재고 현황'!$F:$AI,29,0),0) -> 0 | L12: =IFERROR(VLOOKUP($D12,'[1]DNC 재고 현황'!$F:$AI,30,),0) -> 0 | M12: =K12+L12 -> 0 | N12: =VLOOKUP($D12,'[1]DNC 재고 현황'!$F:$X,19,0) -> 9483 | O12: =IFERROR(IF($M12/$V12>1,100%,IF($M12/$V12<0,0%,$M12/$V12)),"계획없음") -> 0 | P12: =$Y12+$AD12+$AI12+$AN12+$AI12 -> 0 | Q12: =IFERROR(W12/$M$2,0) -> 0 | R12: =IFERROR(M12/$Q12,0) -> 0 | S12: =IFERROR(N12/$Q12,0) -> 0 | T12: =IFERROR(TODAY()+(M12/Q12),"") | U12: =IF(S12<=1,"🔴판매없음",IF(S12<=40,"🟡주의",IF(S12<=60,"🟢안전","✅충분"))) -> 🔴판매없음 | V12: =IFERROR(SUMIF('[1](전체)FCST'!$D:$D,$D12,'[1](전체)FCST'!$H:$H),0) -> 1500 | W12: =IFERROR(VLOOKUP($D12,'[1]판매량,재고(피벗)'!$B:$C,2,0),0) -> 0 | X12: =IFERROR(W12/$M$2*$O$2,0) -> 0 | AA12: =MAX(SUM(N12-X12+Y12),0) -> 9483 | AB12: =IFERROR(AA12/AC12,0) -> 3.161 | AC12: =IFERROR(VLOOKUP($D12,'[1]DNC 재고 현황'!$F:$V,14,0),0) -> 3000 | AD12: =SUMIFS('[1]입고 예정'!$C:$C,'[1]입고 예정'!$A:$A,모니터링!D12,'[1]입고 예정'!$F:$F,모니터링!AD$6) -> 0 | AF12: =MAX(IFERROR(SUM((AA12-AC12)+AD12),0),0) -> 6483 | AG12: =IFERROR(AF12/AH12,0) -> 4.322 | AH12: =IFERROR(VLOOKUP($D12,'[1]DNC 재고 현황'!$F:$V,15,0),0) -> 1500 | AI12: =SUMIFS('[1]입고 예정'!$C:$C,'[1]입고 예정'!$A:$A,모니터링!D12,'[1]입고 예정'!$F:$F,모니터링!AI$6) -> 0 | AK12: =MAX(IFERROR(SUM((AF12-AH12)+AI12),0),0) -> 4983 | AL12: =IFERROR(AK12/AM12,0) -> 3.322 | AM12: =IFERROR(VLOOKUP($D12,'[1]DNC 재고 현황'!$F:$V,16,0),0) -> 1500 | AN12: =SUMIFS('[1]입고 예정'!$C:$C,'[1]입고 예정'!$A:$A,모니터링!D12,'[1]입고 예정'!$F:$F,모니터링!AN$6) -> 0 | AP12: =MAX(IFERROR(SUM((AK12-AM12)+AN12),0),0) -> 3483 | AQ12: =IFERROR(AP12/AR12,0) -> 0.6966 | AR12: =IFERROR(VLOOKUP($D12,'[1]DNC 재고 현황'!$F:$V,17,0),0) -> 5000 | AS12: =SUMIFS('[1]입고 예정'!$C:$C,'[1]입고 예정'!$A:$A,모니터링!D12,'[1]입고 예정'!$F:$F,모니터링!AS$6) -> 0 | AU12: =MAX(IFERROR(AP12-AR12+AS12,0),0) -> 0 | AV12: =IFERROR(AU12/#REF!,0) -> 0
B13: 완제품 | C13: 운영 | D13: 9313808 | E13: =VLOOKUP($D13,'[1]SAP 코드내역'!$A:$D,4,0) -> PDRN_18토닝세럼_1ML*7EA(JP) | H13: 26년 신제품 | I13: 0 | J13: 0 | K13: =IFERROR(VLOOKUP($D13,'[1]DNC 재고 현황'!$F:$AI,29,0),0) -> 0 | L13: =IFERROR(VLOOKUP($D13,'[1]DNC 재고 현황'!$F:$AI,30,),0) -> 0 | M13: =K13+L13 -> 0 | N13: =VLOOKUP($D13,'[1]DNC 재고 현황'!$F:$X,19,0) -> 24 | O13: =IFERROR(IF($M13/$V13>1,100%,IF($M13/$V13<0,0%,$M13/$V13)),"계획없음") -> 0 | P13: =$Y13+$AD13+$AI13+$AN13+$AI13 -> 0 | Q13: =IFERROR(W13/$M$2,0) -> 0 | R13: =IFERROR(M13/$Q13,0) -> 0 | S13: =IFERROR(N13/$Q13,0) -> 0 | T13: =IFERROR(TODAY()+(M13/Q13),"") | U13: =IF(S13<=1,"🔴판매없음",IF(S13<=40,"🟡주의",IF(S13<=60,"🟢안전","✅충분"))) -> 🔴판매없음 | V13: =IFERROR(SUMIF('[1](전체)FCST'!$D:$D,$D13,'[1](전체)FCST'!$H:$H),0) -> 2000 | W13: =IFERROR(VLOOKUP($D13,'[1]판매량,재고(피벗)'!$B:$C,2,0),0) -> 0 | X13: =IFERROR(W13/$M$2*$O$2,0) -> 0 | AA13: =MAX(SUM(N13-X13+Y13),0) -> 24 | AB13: =IFERROR(AA13/AC13,0) -> 0.0024 | AC13: =IFERROR(VLOOKUP($D13,'[1]DNC 재고 현황'!$F:$V,14,0),0) -> 10000 | AD13: =SUMIFS('[1]입고 예정'!$C:$C,'[1]입고 예정'!$A:$A,모니터링!D13,'[1]입고 예정'!$F:$F,모니터링!AD$6) -> 0 | AF13: =MAX(IFERROR(SUM((AA13-AC13)+AD13),0),0) -> 0 | AG13: =IFERROR(AF13/AH13,0) -> 0 | AH13: =IFERROR(VLOOKUP($D13,'[1]DNC 재고 현황'!$F:$V,15,0),0) -> 2000 | AI13: =SUMIFS('[1]입고 예정'!$C:$C,'[1]입고 예정'!$A:$A,모니터링!D13,'[1]입고 예정'!$F:$F,모니터링!AI$6) -> 0 | AK13: =MAX(IFERROR(SUM((AF13-AH13)+AI13),0),0) -> 0 | AL13: =IFERROR(AK13/AM13,0) -> 0 | AM13: =IFERROR(VLOOKUP($D13,'[1]DNC 재고 현황'!$F:$V,16,0),0) -> 0 | AN13: =SUMIFS('[1]입고 예정'!$C:$C,'[1]입고 예정'!$A:$A,모니터링!D13,'[1]입고 예정'!$F:$F,모니터링!AN$6) -> 0 | AP13: =MAX(IFERROR(SUM((AK13-AM13)+AN13),0),0) -> 0 | AQ13: =IFERROR(AP13/AR13,0) -> 0 | AR13: =IFERROR(VLOOKUP($D13,'[1]DNC 재고 현황'!$F:$V,17,0),0) -> 0 | AS13: =SUMIFS('[1]입고 예정'!$C:$C,'[1]입고 예정'!$A:$A,모니터링!D13,'[1]입고 예정'!$F:$F,모니터링!AS$6) -> 0 | AU13: =MAX(IFERROR(AP13-AR13+AS13,0),0) -> 0 | AV13: =IFERROR(AU13/#REF!,0) -> 0
A14: - | B14: 완제품 | C14: 운영 | D14: 9400157 | E14: =VLOOKUP($D14,'[1]SAP 코드내역'!$A:$D,4,0) -> PDRN_18토닝세럼_1ML*7EA_미품(JP) | H14: 신제품 | I14: 0 | J14: 0 | K14: =IFERROR(VLOOKUP($D14,'[1]DNC 재고 현황'!$F:$AI,29,0),0) -> 20000 | L14: =IFERROR(VLOOKUP($D14,'[1]DNC 재고 현황'!$F:$AI,30,),0) -> 0 | M14: =K14+L14 -> 20000 | N14: =VLOOKUP($D14,'[1]DNC 재고 현황'!$F:$X,19,0) -> 20059 | O14: =IFERROR(IF($M14/$V14>1,100%,IF($M14/$V14<0,0%,$M14/$V14)),"계획없음") -> 1 | P14: =$Y14+$AD14+$AI14+$AN14+$AI14 -> 60000 | Q14: =IFERROR(W14/$M$2,0) -> 0 | R14: =IFERROR(M14/$Q14,0) -> 0 | S14: =IFERROR(N14/$Q14,0) -> 0 | T14: =IFERROR(TODAY()+(M14/Q14),"") | U14: =IF(S14<=1,"🔴판매없음",IF(S14<=40,"🟡주의",IF(S14<=60,"🟢안전","✅충분"))) -> 🔴판매없음 | V14: =IFERROR(SUMIF('[1](전체)FCST'!$D:$D,$D14,'[1](전체)FCST'!$H:$H),0) -> 5000 | W14: =IFERROR(VLOOKUP($D14,'[1]판매량,재고(피벗)'!$B:$C,2,0),0) -> 0 | X14: =IFERROR(W14/$M$2*$O$2,0) -> 0 | AA14: =MAX(SUM(N14-X14+Y14),0) -> 20059 | AB14: =IFERROR(AA14/AC14,0) -> 2.0059 | AC14: =IFERROR(VLOOKUP($D14,'[1]DNC 재고 현황'!$F:$V,14,0),0) -> 10000 | AD14: =SUMIFS('[1]입고 예정'!$C:$C,'[1]입고 예정'!$A:$A,모니터링!D14,'[1]입고 예정'!$F:$F,모니터링!AD$6) -> 20000 | AF14: =MAX(IFERROR(SUM((AA14-AC14)+AD14),0),0) -> 30059 | AG14: =IFERROR(AF14/AH14,0) -> 6.0118 | AH14: =IFERROR(VLOOKUP($D14,'[1]DNC 재고 현황'!$F:$V,15,0),0) -> 5000 | AI14: =SUMIFS('[1]입고 예정'!$C:$C,'[1]입고 예정'!$A:$A,모니터링!D14,'[1]입고 예정'!$F:$F,모니터링!AI$6) -> 20000 | AK14: =MAX(IFERROR(SUM((AF14-AH14)+AI14),0),0) -> 45059 | AL14: =IFERROR(AK14/AM14,0) -> 22.5295 | AM14: =IFERROR(VLOOKUP($D14,'[1]DNC 재고 현황'!$F:$V,16,0),0) -> 2000 | AN14: =SUMIFS('[1]입고 예정'!$C:$C,'[1]입고 예정'!$A:$A,모니터링!D14,'[1]입고 예정'!$F:$F,모니터링!AN$6) -> 0 | AP14: =MAX(IFERROR(SUM((AK14-AM14)+AN14),0),0) -> 43059 | AQ14: =IFERROR(AP14/AR14,0) -> 2.15295 | AR14: =IFERROR(VLOOKUP($D14,'[1]DNC 재고 현황'!$F:$V,17,0),0) -> 20000 | AS14: =SUMIFS('[1]입고 예정'!$C:$C,'[1]입고 예정'!$A:$A,모니터링!D14,'[1]입고 예정'!$F:$F,모니터링!AS$6) -> 0 | AU14: =MAX(IFERROR(AP14-AR14+AS14,0),0) -> 23059 | AV14: =IFERROR(AU14/#REF!,0) -> 0
A15: - | B15: 제품 | C15: 운영 | D15: 9305648 | E15: =VLOOKUP($D15,'[1]SAP 코드내역'!$A:$D,4,0) -> 베리어_리페어클렌저_150ml | F15: 코스맥스(주) | I15: 2916.1483 | J15: 12358.325 | K15: =IFERROR(VLOOKUP($D15,'[1]DNC 재고 현황'!$F:$AI,29,0),0) -> 2912 | L15: =IFERROR(VLOOKUP($D15,'[1]DNC 재고 현황'!$F:$AI,30,),0) -> 0 | M15: =K15+L15 -> 2912 | N15: =VLOOKUP($D15,'[1]DNC 재고 현황'!$F:$X,19,0) -> 3546 | O15: =IFERROR(IF($M15/$V15>1,100%,IF($M15/$V15<0,0%,$M15/$V15)),"계획없음") -> 1 | P15: =$Y15+$AD15+$AI15+$AN15+$AI15 -> 0 | Q15: =IFERROR(W15/$M$2,0) -> 36.142857 | R15: =IFERROR(M15/$Q15,0) -> 80.56917 | S15: =IFERROR(N15/$Q15,0) -> 98.110672 | T15: =IFERROR(TODAY()+(M15/Q15),"") -> 46200.569 | U15: =IF(S15<=1,"🔴판매없음",IF(S15<=40,"🟡주의",IF(S15<=60,"🟢안전","✅충분"))) -> ✅충분 | V15: =IFERROR(SUMIF('[1](전체)FCST'!$D:$D,$D15,'[1](전체)FCST'!$H:$H),0) -> 1866.4008 | W15: =IFERROR(VLOOKUP($D15,'[1]판매량,재고(피벗)'!$B:$C,2,0),0) -> 253 | X15: =IFERROR(W15/$M$2*$O$2,0) -> 795.14286 | AA15: =MAX(SUM(N15-X15+Y15),0) -> 2750.8571 | AB15: =IFERROR(AA15/AC15,0) -> 1.3692209 | AC15: =IFERROR(VLOOKUP($D15,'[1]DNC 재고 현황'!$F:$V,14,0),0) -> 2009.0674 | AD15: =SUMIFS('[1]입고 예정'!$C:$C,'[1]입고 예정'!$A:$A,모니터링!D15,'[1]입고 예정'!$F:$F,모니터링!AD$6) -> 0 | AF15: =MAX(IFERROR(SUM((AA15-AC15)+AD15),0),0) -> 741.78971 | AG15: =IFERROR(AF15/AH15,0) -> 0.39744396 | AH15: =IFERROR(VLOOKUP($D15,'[1]DNC 재고 현황'!$F:$V,15,0),0) -> 1866.4008 | AI15: =SUMIFS('[1]입고 예정'!$C:$C,'[1]입고 예정'!$A:$A,모니터링!D15,'[1]입고 예정'!$F:$F,모니터링!AI$6) -> 0 | AK15: =MAX(IFERROR(SUM((AF15-AH15)+AI15),0),0) -> 0 | AL15: =IFERROR(AK15/AM15,0) -> 0 | AM15: =IFERROR(VLOOKUP($D15,'[1]DNC 재고 현황'!$F:$V,16,0),0) -> 1369.6039 | AN15: =SUMIFS('[1]입고 예정'!$C:$C,'[1]입고 예정'!$A:$A,모니터링!D15,'[1]입고 예정'!$F:$F,모니터링!AN$6) -> 0 | AP15: =MAX(IFERROR(SUM((AK15-AM15)+AN15),0),0) -> 0 | AQ15: =IFERROR(AP15/AR15,0) -> 0 | AR15: =IFERROR(VLOOKUP($D15,'[1]DNC 재고 현황'!$F:$V,17,0),0) -> 1684.6039 | AS15: =SUMIFS('[1]입고 예정'!$C:$C,'[1]입고 예정'!$A:$A,모니터링!D15,'[1]입고 예정'!$F:$F,모니터링!AS$6) -> 0 | AU15: =MAX(IFERROR(AP15-AR15+AS15,0),0) -> 0 | AV15: =IFERROR(AU15/#REF!,0) -> 0
D16: 9313190 | E16: =VLOOKUP($D16,'[1]SAP 코드내역'!$A:$D,4,0) -> [임가공]멜라_토닝원데이앰플_부스터샷_본품+리필15ml_카카오기획세트 | K16: =IFERROR(VLOOKUP($D16,'[1]DNC 재고 현황'!$F:$AI,29,0),0) -> 171 | L16: =IFERROR(VLOOKUP($D16,'[1]DNC 재고 현황'!$F:$AI,30,),0) -> 0 | M16: =K16+L16 -> 171 | N16: =VLOOKUP($D16,'[1]DNC 재고 현황'!$F:$X,19,0) -> 171 | O16: =IFERROR(IF($M16/$V16>1,100%,IF($M16/$V16<0,0%,$M16/$V16)),"계획없음") -> 1 | P16: =$Y16+$AD16+$AI16+$AN16+$AI16 -> 0 | Q16: =IFERROR(W16/$M$2,0) -> 2.1428571 | R16: =IFERROR(M16/$Q16,0) -> 79.8 | S16: =IFERROR(N16/$Q16,0) -> 79.8 | T16: =IFERROR(TODAY()+(M16/Q16),"") -> 46199.8 | U16: =IF(S16<=1,"🔴판매없음",IF(S16<=40,"🟡주의",IF(S16<=60,"🟢안전","✅충분"))) -> ✅충분 | V16: =IFERROR(SUMIF('[1](전체)FCST'!$D:$D,$D16,'[1](전체)FCST'!$H:$H),0) -> 74.575442 | W16: =IFERROR(VLOOKUP($D16,'[1]판매량,재고(피벗)'!$B:$C,2,0),0) -> 15 | X16: =IFERROR(W16/$M$2*$O$2,0) -> 47.142857 | AA16: =MAX(SUM(N16-X16+Y16),0) -> 123.85714 | AB16: =IFERROR(AA16/AC16,0) -> 1.6608302 | AC16: =IFERROR(VLOOKUP($D16,'[1]DNC 재고 현황'!$F:$V,14,0),0) -> 74.575442 | AD16: =SUMIFS('[1]입고 예정'!$C:$C,'[1]입고 예정'!$A:$A,모니터링!D45,'[1]입고 예정'!$F:$F,모니터링!AD$6) -> 0 | AF16: =MAX(IFERROR(SUM((AA16-AC16)+AD16),0),0) -> 49.281701 | AG16: =IFERROR(AF16/AH16,0) -> 0.66083016 | AH16: =IFERROR(VLOOKUP($D16,'[1]DNC 재고 현황'!$F:$V,15,0),0) -> 74.575442 | AI16: =SUMIFS('[1]입고 예정'!$C:$C,'[1]입고 예정'!$A:$A,모니터링!D45,'[1]입고 예정'!$F:$F,모니터링!AI$6) -> 0 | AK16: =MAX(IFERROR(SUM((AF16-AH16)+AI16),0),0) -> 0 | AL16: =IFERROR(AK16/AM16,0) -> 0 | AM16: =IFERROR(VLOOKUP($D16,'[1]DNC 재고 현황'!$F:$V,16,0),0) -> 100 | AN16: =SUMIFS('[1]입고 예정'!$C:$C,'[1]입고 예정'!$A:$A,모니터링!D45,'[1]입고 예정'!$F:$F,모니터링!AN$6) -> 0 | AP16: =MAX(IFERROR(SUM((AK16-AM16)+AN16),0),0) -> 0 | AQ16: =IFERROR(AP16/AR16,0) -> 0 | AR16: =IFERROR(VLOOKUP($D16,'[1]DNC 재고 현황'!$F:$V,17,0),0) -> 100 | AS16: =SUMIFS('[1]입고 예정'!$C:$C,'[1]입고 예정'!$A:$A,모니터링!D45,'[1]입고 예정'!$F:$F,모니터링!AS$6) -> 0 | AU16: =MAX(IFERROR(AP16-AR16+AS16,0),0) -> 0 | AV16: =IFERROR(AU16/#REF!,0) -> 0
A17: - | B17: 완제품 | C17: 운영 | D17: 9313047 | E17: =VLOOKUP($D17,'[1]SAP 코드내역'!$A:$D,4,0) -> 멜라_토닝앰플파운데이션_21호내추럴15ml | H17: 신제품 | I17: 3461.2939 | J17: 27080.182 | K17: =IFERROR(VLOOKUP($D17,'[1]DNC 재고 현황'!$F:$AI,29,0),0) -> 6799 | L17: =IFERROR(VLOOKUP($D17,'[1]DNC 재고 현황'!$F:$AI,30,),0) -> 0 | M17: =K17+L17 -> 6799 | N17: =VLOOKUP($D17,'[1]DNC 재고 현황'!$F:$X,19,0) -> 6799 | O17: =IFERROR(IF($M17/$V17>1,100%,IF($M17/$V17<0,0%,$M17/$V17)),"계획없음") -> 1 | P17: =$Y17+$AD17+$AI17+$AN17+$AI17 -> 8600 | Q17: =IFERROR(W17/$M$2,0) -> 43.714286 | R17: =IFERROR(M17/$Q17,0) -> 155.53268 | S17: =IFERROR(N17/$Q17,0) -> 155.53268 | T17: =IFERROR(TODAY()+(M17/Q17),"") -> 46275.533 | U17: =IF(S17<=1,"🔴판매없음",IF(S17<=40,"🟡주의",IF(S17<=60,"🟢안전","✅충분"))) -> ✅충분 | V17: =IFERROR(SUMIF('[1](전체)FCST'!$D:$D,$D17,'[1](전체)FCST'!$H:$H),0) -> 3132.7731 | W17: =IFERROR(VLOOKUP($D17,'[1]판매량,재고(피벗)'!$B:$C,2,0),0) -> 306 | X17: =IFERROR(W17/$M$2*$O$2,0) -> 961.71429 | AA17: =MAX(SUM(N17-X17+Y17),0) -> 5837.2857 | AB17: =IFERROR(AA17/AC17,0) -> 1.8590495 | AC17: =IFERROR(VLOOKUP($D17,'[1]DNC 재고 현황'!$F:$V,14,0),0) -> 3139.9303 | AD17: =SUMIFS('[1]입고 예정'!$C:$C,'[1]입고 예정'!$A:$A,모니터링!D17,'[1]입고 예정'!$F:$F,모니터링!AD$6) -> 8600 | AF17: =MAX(IFERROR(SUM((AA17-AC17)+AD17),0),0) -> 11297.355 | AG17: =IFERROR(AF17/AH17,0) -> 3.6061838 | AH17: =IFERROR(VLOOKUP($D17,'[1]DNC 재고 현황'!$F:$V,15,0),0) -> 3132.7731 | AI17: =SUMIFS('[1]입고 예정'!$C:$C,'[1]입고 예정'!$A:$A,모니터링!D17,'[1]입고 예정'!$F:$F,모니터링!AI$6) -> 0 | AK17: =MAX(IFERROR(SUM((AF17-AH17)+AI17),0),0) -> 8164.5824 | AL17: =IFERROR(AK17/AM17,0) -> 2.6142331 | AM17: =IFERROR(VLOOKUP($D17,'[1]DNC 재고 현황'!$F:$V,16,0),0) -> 3123.1271 | AN17: =SUMIFS('[1]입고 예정'!$C:$C,'[1]입고 예정'!$A:$A,모니터링!D17,'[1]입고 예정'!$F:$F,모니터링!AN$6) -> 0 | AP17: =MAX(IFERROR(SUM((AK17-AM17)+AN17),0),0) -> 5041.4552 | AQ17: =IFERROR(AP17/AR17,0) -> 1.6142331 | AR17: =IFERROR(VLOOKUP($D17,'[1]DNC 재고 현황'!$F:$V,17,0),0) -> 3123.1271 | AS17: =SUMIFS('[1]입고 예정'!$C:$C,'[1]입고 예정'!$A:$A,모니터링!D17,'[1]입고 예정'!$F:$F,모니터링!AS$6) -> 0 | AU17: =MAX(IFERROR(AP17-AR17+AS17,0),0) -> 1918.3281 | AV17: =IFERROR(AU17/#REF!,0) -> 0
A18: - | B18: 제품 | C18: 운영 | D18: 9301416 | E18: =VLOOKUP($D18,'[1]SAP 코드내역'!$A:$D,4,0) -> DWEGF_화이트토닝크림_2ml샤세 | F18: 0 | I18: 113.58543 | J18: 1005.8831 | K18: =IFERROR(VLOOKUP($D18,'[1]DNC 재고 현황'!$F:$AI,29,0),0) -> 0 | L18: =IFERROR(VLOOKUP($D18,'[1]DNC 재고 현황'!$F:$AI,30,),0) -> 0 | M18: =K18+L18 -> 0 | N18: =VLOOKUP($D18,'[1]DNC 재고 현황'!$F:$X,19,0) -> 0 | O18: =IFERROR(IF($M18/$V18>1,100%,IF($M18/$V18<0,0%,$M18/$V18)),"계획없음") -> 0 | P18: =$Y18+$AD18+$AI18+$AN18+$AI18 -> 0 | Q18: =IFERROR(W18/$M$2,0) -> 0 | R18: =IFERROR(M18/$Q18,0) -> 0 | S18: =IFERROR(N18/$Q18,0) -> 0 | T18: =IFERROR(TODAY()+(M18/Q18),"") | U18: =IF(S18<=1,"🔴판매없음",IF(S18<=40,"🟡주의",IF(S18<=60,"🟢안전","✅충분"))) -> 🔴판매없음 | V18: =IFERROR(SUMIF('[1](전체)FCST'!$D:$D,$D18,'[1](전체)FCST'!$H:$H),0) -> 46.049929 | W18: =IFERROR(VLOOKUP($D18,'[1]판매량,재고(피벗)'!$B:$C,2,0),0) -> 0 | X18: =IFERROR(W18/$M$2*$O$2,0) -> 0 | AA18: =MAX(SUM(N18-X18+Y18),0) -> 0 | AB18: =IFERROR(AA18/AC18,0) -> 0 | AC18: =IFERROR(VLOOKUP($D18,'[1]DNC 재고 현황'!$F:$V,14,0),0) -> 50.963479 | AD18: =SUMIFS('[1]입고 예정'!$C:$C,'[1]입고 예정'!$A:$A,모니터링!D18,'[1]입고 예정'!$F:$F,모니터링!AD$6) -> 0 | AF18: =MAX(IFERROR(SUM((AA18-AC18)+AD18),0),0) -> 0 | AG18: =IFERROR(AF18/AH18,0) -> 0 | AH18: =IFERROR(VLOOKUP($D18,'[1]DNC 재고 현황'!$F:$V,15,0),0) -> 46.049929 | AI18: =SUMIFS('[1]입고 예정'!$C:$C,'[1]입고 예정'!$A:$A,모니터링!D18,'[1]입고 예정'!$F:$F,모니터링!AI$6) -> 0 | AK18: =MAX(IFERROR(SUM((AF18-AH18)+AI18),0),0) -> 0 | AL18: =IFERROR(AK18/AM18,0) -> 0 | AM18: =IFERROR(VLOOKUP($D18,'[1]DNC 재고 현황'!$F:$V,16,0),0) -> 0 | AN18: =SUMIFS('[1]입고 예정'!$C:$C,'[1]입고 예정'!$A:$A,모니터링!D18,'[1]입고 예정'!$F:$F,모니터링!AN$6) -> 0 | AP18: =MAX(IFERROR(SUM((AK18-AM18)+AN18),0),0) -> 0 | AQ18: =IFERROR(AP18/AR18,0) -> 0 | AR18: =IFERROR(VLOOKUP($D18,'[1]DNC 재고 현황'!$F:$V,17,0),0) -> 0 | AS18: =SUMIFS('[1]입고 예정'!$C:$C,'[1]입고 예정'!$A:$A,모니터링!D18,'[1]입고 예정'!$F:$F,모니터링!AS$6) -> 0 | AU18: =MAX(IFERROR(AP18-AR18+AS18,0),0) -> 0 | AV18: =IFERROR(AU18/#REF!,0) -> 0
A19: - | B19: 완제품 | C19: 운영 | D19: 9313048 | E19: =VLOOKUP($D19,'[1]SAP 코드내역'!$A:$D,4,0) -> 멜라_토닝앰플파운데이션_22호라이트베이지_15ml | H19: 신제품 | I19: 0 | J19: 27252.998 | K19: =IFERROR(VLOOKUP($D19,'[1]DNC 재고 현황'!$F:$AI,29,0),0) -> 3348 | L19: =IFERROR(VLOOKUP($D19,'[1]DNC 재고 현황'!$F:$AI,30,),0) -> 0 | M19: =K19+L19 -> 3348 | N19: =VLOOKUP($D19,'[1]DNC 재고 현황'!$F:$X,19,0) -> 3348 | O19: =IFERROR(IF($M19/$V19>1,100%,IF($M19/$V19<0,0%,$M19/$V19)),"계획없음") -> 1 | P19: =$Y19+$AD19+$AI19+$AN19+$AI19 -> 3400 | Q19: =IFERROR(W19/$M$2,0) -> 20.142857 | R19: =IFERROR(M19/$Q19,0) -> 166.21277 | S19: =IFERROR(N19/$Q19,0) -> 166.21277 | T19: =IFERROR(TODAY()+(M19/Q19),"") -> 46286.213 | U19: =IF(S19<=1,"🔴판매없음",IF(S19<=40,"🟡주의",IF(S19<=60,"🟢안전","✅충분"))) -> ✅충분 | V19: =IFERROR(SUMIF('[1](전체)FCST'!$D:$D,$D19,'[1](전체)FCST'!$H:$H),0) -> 1308.3235 | W19: =IFERROR(VLOOKUP($D19,'[1]판매량,재고(피벗)'!$B:$C,2,0),0) -> 141 | X19: =IFERROR(W19/$M$2*$O$2,0) -> 443.14286 | AA19: =MAX(SUM(N19-X19+Y19),0) -> 2904.8571 | AB19: =IFERROR(AA19/AC19,0) -> 2.2082578 | AC19: =IFERROR(VLOOKUP($D19,'[1]DNC 재고 현황'!$F:$V,14,0),0) -> 1315.452 | AD19: =SUMIFS('[1]입고 예정'!$C:$C,'[1]입고 예정'!$A:$A,모니터링!D19,'[1]입고 예정'!$F:$F,모니터링!AD$6) -> 3400 | AF19: =MAX(IFERROR(SUM((AA19-AC19)+AD19),0),0) -> 4989.4051 | AG19: =IFERROR(AF19/AH19,0) -> 3.8135867 | AH19: =IFERROR(VLOOKUP($D19,'[1]DNC 재고 현황'!$F:$V,15,0),0) -> 1308.3235 | AI19: =SUMIFS('[1]입고 예정'!$C:$C,'[1]입고 예정'!$A:$A,모니터링!D19,'[1]입고 예정'!$F:$F,모니터링!AI$6) -> 0 | AK19: =MAX(IFERROR(SUM((AF19-AH19)+AI19),0),0) -> 3681.0816 | AL19: =IFERROR(AK19/AM19,0) -> 2.8133955 | AM19: =IFERROR(VLOOKUP($D19,'[1]DNC 재고 현황'!$F:$V,16,0),0) -> 1308.4124 | AN19: =SUMIFS('[1]입고 예정'!$C:$C,'[1]입고 예정'!$A:$A,모니터링!D19,'[1]입고 예정'!$F:$F,모니터링!AN$6) -> 0 | AP19: =MAX(IFERROR(SUM((AK19-AM19)+AN19),0),0) -> 2372.6692 | AQ19: =IFERROR(AP19/AR19,0) -> 1.8133955 | AR19: =IFERROR(VLOOKUP($D19,'[1]DNC 재고 현황'!$F:$V,17,0),0) -> 1308.4124 | AS19: =SUMIFS('[1]입고 예정'!$C:$C,'[1]입고 예정'!$A:$A,모니터링!D19,'[1]입고 예정'!$F:$F,모니터링!AS$6) -> 0 | AU19: =MAX(IFERROR(AP19-AR19+AS19,0),0) -> 1064.2568 | AV19: =IFERROR(AU19/#REF!,0) -> 0
A20: - | B20: 제품 | C20: 운영 | D20: 9301415 | E20: =VLOOKUP($D20,'[1]SAP 코드내역'!$A:$D,4,0) -> DWEGF_화이트토닝크림_50ml | F20: 코스맥스(주) | I20: 2532.8522 | J20: 19345.838 | K20: =IFERROR(VLOOKUP($D20,'[1]DNC 재고 현황'!$F:$AI,29,0),0) -> 0 | L20: =IFERROR(VLOOKUP($D20,'[1]DNC 재고 현황'!$F:$AI,30,),0) -> 13 | M20: =K20+L20 -> 13 | N20: =VLOOKUP($D20,'[1]DNC 재고 현황'!$F:$X,19,0) -> 13 | O20: =IFERROR(IF($M20/$V20>1,100%,IF($M20/$V20<0,0%,$M20/$V20)),"계획없음") -> 0.0051724499 | P20: =$Y20+$AD20+$AI20+$AN20+$AI20 -> 20000 | Q20: =IFERROR(W20/$M$2,0) -> 0 | R20: =IFERROR(M20/$Q20,0) -> 0 | S20: =IFERROR(N20/$Q20,0) -> 0 | T20: =IFERROR(TODAY()+(M20/Q20),"") | U20: =IF(S20<=1,"🔴판매없음",IF(S20<=40,"🟡주의",IF(S20<=60,"🟢안전","✅충분"))) -> 🔴판매없음 | V20: =IFERROR(SUMIF('[1](전체)FCST'!$D:$D,$D20,'[1](전체)FCST'!$H:$H),0) -> 2513.3158 | W20: =IFERROR(VLOOKUP($D20,'[1]판매량,재고(피벗)'!$B:$C,2,0),0) -> 0 | X20: =IFERROR(W20/$M$2*$O$2,0) -> 0 | AA20: =MAX(SUM(N20-X20+Y20),0) -> 13 | AB20: =IFERROR(AA20/AC20,0) -> 0.0051930641 | AC20: =IFERROR(VLOOKUP($D20,'[1]DNC 재고 현황'!$F:$V,14,0),0) -> 2503.339 | AD20: =SUMIFS('[1]입고 예정'!$C:$C,'[1]입고 예정'!$A:$A,모니터링!D20,'[1]입고 예정'!$F:$F,모니터링!AD$6) -> 0 | AF20: =MAX(IFERROR(SUM((AA20-AC20)+AD20),0),0) -> 0 | AG20: =IFERROR(AF20/AH20,0) -> 0 | AH20: =IFERROR(VLOOKUP($D20,'[1]DNC 재고 현황'!$F:$V,15,0),0) -> 2513.3158 | AI20: =SUMIFS('[1]입고 예정'!$C:$C,'[1]입고 예정'!$A:$A,모니터링!D20,'[1]입고 예정'!$F:$F,모니터링!AI$6) -> 10000 | AK20: =MAX(IFERROR(SUM((AF20-AH20)+AI20),0),0) -> 7486.6842 | AL20: =IFERROR(AK20/AM20,0) -> 0 | AM20: =IFERROR(VLOOKUP($D20,'[1]DNC 재고 현황'!$F:$V,16,0),0) -> 0 | AN20: =SUMIFS('[1]입고 예정'!$C:$C,'[1]입고 예정'!$A:$A,모니터링!D20,'[1]입고 예정'!$F:$F,모니터링!AN$6) -> 0 | AP20: =MAX(IFERROR(SUM((AK20-AM20)+AN20),0),0) -> 7486.6842 | AQ20: =IFERROR(AP20/AR20,0) -> 0 | AR20: =IFERROR(VLOOKUP($D20,'[1]DNC 재고 현황'!$F:$V,17,0),0) -> 0 | AS20: =SUMIFS('[1]입고 예정'!$C:$C,'[1]입고 예정'!$A:$A,모니터링!D20,'[1]입고 예정'!$F:$F,모니터링!AS$6) -> 0 | AU20: =MAX(IFERROR(AP20-AR20+AS20,0),0) -> 7486.6842 | AV20: =IFERROR(AU20/#REF!,0) -> 0
A21: - | B21: 제품 | C21: 운영 | D21: 9311067 | E21: =VLOOKUP($D21,'[1]SAP 코드내역'!$A:$D,4,0) -> 멜라_비타민C부스팅앰플_15g_리뉴얼 | F21: 코스맥스(주) | I21: 4281.6673 | J21: 30339.832 | K21: =IFERROR(VLOOKUP($D21,'[1]DNC 재고 현황'!$F:$AI,29,0),0) -> 7 | L21: =IFERROR(VLOOKUP($D21,'[1]DNC 재고 현황'!$F:$AI,30,),0) -> 0 | M21: =K21+L21 -> 7 | N21: =VLOOKUP($D21,'[1]DNC 재고 현황'!$F:$X,19,0) -> 328 | O21: =IFERROR(IF($M21/$V21>1,100%,IF($M21/$V21<0,0%,$M21/$V21)),"계획없음") -> 0.0034285304 | P21: =$Y21+$AD21+$AI21+$AN21+$AI21 -> 11000 | Q21: =IFERROR(W21/$M$2,0) -> 2.5714286 | R21: =IFERROR(M21/$Q21,0) -> 2.7222222 | S21: =IFERROR(N21/$Q21,0) -> 127.55556 | T21: =IFERROR(TODAY()+(M21/Q21),"") -> 46122.722 | U21: =IF(S21<=1,"🔴판매없음",IF(S21<=40,"🟡주의",IF(S21<=60,"🟢안전","✅충분"))) -> ✅충분 | V21: =IFERROR(SUMIF('[1](전체)FCST'!$D:$D,$D21,'[1](전체)FCST'!$H:$H),0) -> 2041.6911 | W21: =IFERROR(VLOOKUP($D21,'[1]판매량,재고(피벗)'!$B:$C,2,0),0) -> 18 | X21: =IFERROR(W21/$M$2*$O$2,0) -> 56.571429 | AA21: =MAX(SUM(N21-X21+Y21),0) -> 271.42857 | AB21: =IFERROR(AA21/AC21,0) -> 0.23709303 | AC21: =IFERROR(VLOOKUP($D21,'[1]DNC 재고 현황'!$F:$V,14,0),0) -> 1144.8189 | AD21: =SUMIFS('[1]입고 예정'!$C:$C,'[1]입고 예정'!$A:$A,모니터링!D21,'[1]입고 예정'!$F:$F,모니터링!AD$6) -> 5000 | AF21: =MAX(IFERROR(SUM((AA21-AC21)+AD21),0),0) -> 4126.6097 | AG21: =IFERROR(AF21/AH21,0) -> 2.0211724 | AH21: =IFERROR(VLOOKUP($D21,'[1]DNC 재고 현황'!$F:$V,15,0),0) -> 2041.6911 | AI21: =SUMIFS('[1]입고 예정'!$C:$C,'[1]입고 예정'!$A:$A,모니터링!D21,'[1]입고 예정'!$F:$F,모니터링!AI$6) -> 3000 | AK21: =MAX(IFERROR(SUM((AF21-AH21)+AI21),0),0) -> 5084.9186 | AL21: =IFERROR(AK21/AM21,0) -> 1.5074834 | AM21: =IFERROR(VLOOKUP($D21,'[1]DNC 재고 현황'!$F:$V,16,0),0) -> 3373.1175 | AN21: =SUMIFS('[1]입고 예정'!$C:$C,'[1]입고 예정'!$A:$A,모니터링!D21,'[1]입고 예정'!$F:$F,모니터링!AN$6) -> 0 | AP21: =MAX(IFERROR(SUM((AK21-AM21)+AN21),0),0) -> 1711.8011 | AQ21: =IFERROR(AP21/AR21,0) -> 0.7914415 | AR21: =IFERROR(VLOOKUP($D21,'[1]DNC 재고 현황'!$F:$V,17,0),0) -> 2162.8903 | AS21: =SUMIFS('[1]입고 예정'!$C:$C,'[1]입고 예정'!$A:$A,모니터링!D21,'[1]입고 예정'!$F:$F,모니터링!AS$6) -> 0 | AU21: =MAX(IFERROR(AP21-AR21+AS21,0),0) -> 0 | AV21: =IFERROR(AU21/#REF!,0) -> 0
A22: - | B22: 제품 | C22: 소진후 단종 | D22: 9310964 | E22: =VLOOKUP($D22,'[1]SAP 코드내역'!$A:$D,4,0) -> [세트_임가공]멜라_로즈앰플15ml+로즈미스트50ml_듀오세트(카카오) | F22: (주)이지메디컴 | I22: 13785.651 | J22: 45363.976 | K22: =IFERROR(VLOOKUP($D22,'[1]DNC 재고 현황'!$F:$AI,29,0),0) -> 1 | L22: =IFERROR(VLOOKUP($D22,'[1]DNC 재고 현황'!$F:$AI,30,),0) -> 0 | M22: =K22+L22 -> 1 | N22: =VLOOKUP($D22,'[1]DNC 재고 현황'!$F:$X,19,0) -> 1 | O22: =IFERROR(IF($M22/$V22>1,100%,IF($M22/$V22<0,0%,$M22/$V22)),"계획없음") -> 0.046618817 | P22: =$Y22+$AD22+$AI22+$AN22+$AI22 -> 0 | Q22: =IFERROR(W22/$M$2,0) -> 0 | R22: =IFERROR(M22/$Q22,0) -> 0 | S22: =IFERROR(N22/$Q22,0) -> 0 | T22: =IFERROR(TODAY()+(M22/Q22),"") | U22: =IF(S22<=1,"🔴판매없음",IF(S22<=40,"🟡주의",IF(S22<=60,"🟢안전","✅충분"))) -> 🔴판매없음 | V22: =IFERROR(SUMIF('[1](전체)FCST'!$D:$D,$D22,'[1](전체)FCST'!$H:$H),0) -> 21.450566 | W22: =IFERROR(VLOOKUP($D22,'[1]판매량,재고(피벗)'!$B:$C,2,0),0) -> 0 | X22: =IFERROR(W22/$M$2*$O$2,0) -> 0 | AA22: =MAX(SUM(N22-X22+Y22),0) -> 1 | AB22: =IFERROR(AA22/AC22,0) -> 0.046618817 | AC22: =IFERROR(VLOOKUP($D22,'[1]DNC 재고 현황'!$F:$V,14,0),0) -> 21.450566 | AD22: =SUMIFS('[1]입고 예정'!$C:$C,'[1]입고 예정'!$A:$A,모니터링!D22,'[1]입고 예정'!$F:$F,모니터링!AD$6) -> 0 | AF22: =MAX(IFERROR(SUM((AA22-AC22)+AD22),0),0) -> 0 | AG22: =IFERROR(AF22/AH22,0) -> 0 | AH22: =IFERROR(VLOOKUP($D22,'[1]DNC 재고 현황'!$F:$V,15,0),0) -> 21.450566 | AI22: =SUMIFS('[1]입고 예정'!$C:$C,'[1]입고 예정'!$A:$A,모니터링!D22,'[1]입고 예정'!$F:$F,모니터링!AI$6) -> 0 | AK22: =MAX(IFERROR(SUM((AF22-AH22)+AI22),0),0) -> 0 | AL22: =IFERROR(AK22/AM22,0) -> 0 | AM22: =IFERROR(VLOOKUP($D22,'[1]DNC 재고 현황'!$F:$V,16,0),0) -> 0 | AN22: =SUMIFS('[1]입고 예정'!$C:$C,'[1]입고 예정'!$A:$A,모니터링!D22,'[1]입고 예정'!$F:$F,모니터링!AN$6) -> 0 | AP22: =MAX(IFERROR(SUM((AK22-AM22)+AN22),0),0) -> 0 | AQ22: =IFERROR(AP22/AR22,0) -> 0 | AR22: =IFERROR(VLOOKUP($D22,'[1]DNC 재고 현황'!$F:$V,17,0),0) -> 0 | AS22: =SUMIFS('[1]입고 예정'!$C:$C,'[1]입고 예정'!$A:$A,모니터링!D22,'[1]입고 예정'!$F:$F,모니터링!AS$6) -> 0 | AU22: =MAX(IFERROR(AP22-AR22+AS22,0),0) -> 0 | AV22: =IFERROR(AU22/#REF!,0) -> 0
A23: - | B23: 제품 | C23: 운영 | D23: 9307278 | E23: =VLOOKUP($D23,'[1]SAP 코드내역'!$A:$D,4,0) -> (단종)멜라_라라필_스텝1_50ml | F23: (주)닥터제이코스 | I23: 6078.8244 | J23: 38151.267 | K23: =IFERROR(VLOOKUP($D23,'[1]DNC 재고 현황'!$F:$AI,29,0),0) -> 0 | L23: =IFERROR(VLOOKUP($D23,'[1]DNC 재고 현황'!$F:$AI,30,),0) -> 0 | M23: =K23+L23 -> 0 | N23: =VLOOKUP($D23,'[1]DNC 재고 현황'!$F:$X,19,0) -> 10297 | O23: =IFERROR(IF($M23/$V23>1,100%,IF($M23/$V23<0,0%,$M23/$V23)),"계획없음") -> 0 | P23: =$Y23+$AD23+$AI23+$AN23+$AI23 -> 0 | Q23: =IFERROR(W23/$M$2,0) -> 0 | R23: =IFERROR(M23/$Q23,0) -> 0 | S23: =IFERROR(N23/$Q23,0) -> 0 | T23: =IFERROR(TODAY()+(M23/Q23),"") | U23: =IF(S23<=1,"🔴판매없음",IF(S23<=40,"🟡주의",IF(S23<=60,"🟢안전","✅충분"))) -> 🔴판매없음 | V23: =IFERROR(SUMIF('[1](전체)FCST'!$D:$D,$D23,'[1](전체)FCST'!$H:$H),0) -> 130.42414 | W23: =IFERROR(VLOOKUP($D23,'[1]판매량,재고(피벗)'!$B:$C,2,0),0) -> 0 | X23: =IFERROR(W23/$M$2*$O$2,0) -> 0 | AA23: =MAX(SUM(N23-X23+Y23),0) -> 10297 | AB23: =IFERROR(AA23/AC23,0) -> 48.9345 | AC23: =IFERROR(VLOOKUP($D23,'[1]DNC 재고 현황'!$F:$V,14,0),0) -> 210.42414 | AD23: =SUMIFS('[1]입고 예정'!$C:$C,'[1]입고 예정'!$A:$A,모니터링!D23,'[1]입고 예정'!$F:$F,모니터링!AD$6) -> 0 | AF23: =MAX(IFERROR(SUM((AA23-AC23)+AD23),0),0) -> 10086.576 | AG23: =IFERROR(AF23/AH23,0) -> 77.336726 | AH23: =IFERROR(VLOOKUP($D23,'[1]DNC 재고 현황'!$F:$V,15,0),0) -> 130.42414 | AI23: =SUMIFS('[1]입고 예정'!$C:$C,'[1]입고 예정'!$A:$A,모니터링!D23,'[1]입고 예정'!$F:$F,모니터링!AI$6) -> 0 | AK23: =MAX(IFERROR(SUM((AF23-AH23)+AI23),0),0) -> 9956.1517 | AL23: =IFERROR(AK23/AM23,0) -> 4.6733191 | AM23: =IFERROR(VLOOKUP($D23,'[1]DNC 재고 현황'!$F:$V,16,0),0) -> 2130.4241 | AN23: =SUMIFS('[1]입고 예정'!$C:$C,'[1]입고 예정'!$A:$A,모니터링!D23,'[1]입고 예정'!$F:$F,모니터링!AN$6) -> 0 | AP23: =MAX(IFERROR(SUM((AK23-AM23)+AN23),0),0) -> 7825.7276 | AQ23: =IFERROR(AP23/AR23,0) -> 12.820148 | AR23: =IFERROR(VLOOKUP($D23,'[1]DNC 재고 현황'!$F:$V,17,0),0) -> 610.42414 | AS23: =SUMIFS('[1]입고 예정'!$C:$C,'[1]입고 예정'!$A:$A,모니터링!D23,'[1]입고 예정'!$F:$F,모니터링!AS$6) -> 0 | AU23: =MAX(IFERROR(AP23-AR23+AS23,0),0) -> 7215.3034 | AV23: =IFERROR(AU23/#REF!,0) -> 0
A24: - | B24: 판촉물 | C24: 운영 | D24: 7301751 | E24: =VLOOKUP($D24,'[1]SAP 코드내역'!$A:$D,4,0) -> (단종)[판촉물_쇼핑백]24년추석_미니 | F24: 고문당인쇄(주) | I24: 250 | J24: 409.41393 | K24: =IFERROR(VLOOKUP($D24,'[1]DNC 재고 현황'!$F:$AI,29,0),0) -> 0 | L24: =IFERROR(VLOOKUP($D24,'[1]DNC 재고 현황'!$F:$AI,30,),0) -> 2 | M24: =K24+L24 -> 2 | N24: =VLOOKUP($D24,'[1]DNC 재고 현황'!$F:$X,19,0) -> 2 | O24: =IFERROR(IF($M24/$V24>1,100%,IF($M24/$V24<0,0%,$M24/$V24)),"계획없음") -> 0.083658039 | P24: =$Y24+$AD24+$AI24+$AN24+$AI24 -> 0 | Q24: =IFERROR(W24/$M$2,0) -> 0 | R24: =IFERROR(M24/$Q24,0) -> 0 | S24: =IFERROR(N24/$Q24,0) -> 0 | T24: =IFERROR(TODAY()+(M24/Q24),"") | U24: =IF(S24<=1,"🔴판매없음",IF(S24<=40,"🟡주의",IF(S24<=60,"🟢안전","✅충분"))) -> 🔴판매없음 | V24: =IFERROR(SUMIF('[1](전체)FCST'!$D:$D,$D24,'[1](전체)FCST'!$H:$H),0) -> 23.906848 | W24: =IFERROR(VLOOKUP($D24,'[1]판매량,재고(피벗)'!$B:$C,2,0),0) -> 0 | X24: =IFERROR(W24/$M$2*$O$2,0) -> 0 | AA24: =MAX(SUM(N24-X24+Y24),0) -> 2 | AB24: =IFERROR(AA24/AC24,0) -> 0.075592303 | AC24: =IFERROR(VLOOKUP($D24,'[1]DNC 재고 현황'!$F:$V,14,0),0) -> 26.45772 | AD24: =SUMIFS('[1]입고 예정'!$C:$C,'[1]입고 예정'!$A:$A,모니터링!D24,'[1]입고 예정'!$F:$F,모니터링!AD$6) -> 0 | AF24: =MAX(IFERROR(SUM((AA24-AC24)+AD24),0),0) -> 0 | AG24: =IFERROR(AF24/AH24,0) -> 0 | AH24: =IFERROR(VLOOKUP($D24,'[1]DNC 재고 현황'!$F:$V,15,0),0) -> 23.906848 | AI24: =SUMIFS('[1]입고 예정'!$C:$C,'[1]입고 예정'!$A:$A,모니터링!D24,'[1]입고 예정'!$F:$F,모니터링!AI$6) -> 0 | AK24: =MAX(IFERROR(SUM((AF24-AH24)+AI24),0),0) -> 0 | AL24: =IFERROR(AK24/AM24,0) -> 0 | AM24: =IFERROR(VLOOKUP($D24,'[1]DNC 재고 현황'!$F:$V,16,0),0) -> 0 | AN24: =SUMIFS('[1]입고 예정'!$C:$C,'[1]입고 예정'!$A:$A,모니터링!D24,'[1]입고 예정'!$F:$F,모니터링!AN$6) -> 0 | AP24: =MAX(IFERROR(SUM((AK24-AM24)+AN24),0),0) -> 0 | AQ24: =IFERROR(AP24/AR24,0) -> 0 | AR24: =IFERROR(VLOOKUP($D24,'[1]DNC 재고 현황'!$F:$V,17,0),0) -> 0 | AS24: =SUMIFS('[1]입고 예정'!$C:$C,'[1]입고 예정'!$A:$A,모니터링!D24,'[1]입고 예정'!$F:$F,모니터링!AS$6) -> 0 | AU24: =MAX(IFERROR(AP24-AR24+AS24,0),0) -> 0 | AV24: =IFERROR(AU24/#REF!,0) -> 0
A25: - | B25: 제품 | C25: 소진후 단종 | D25: 9307138 | E25: =VLOOKUP($D25,'[1]SAP 코드내역'!$A:$D,4,0) -> (단종)멜라_에센스크림_45ml | F25: 코스맥스(주) | I25: 3262.9566 | J25: 12900.112 | K25: =IFERROR(VLOOKUP($D25,'[1]DNC 재고 현황'!$F:$AI,29,0),0) -> 0 | L25: =IFERROR(VLOOKUP($D25,'[1]DNC 재고 현황'!$F:$AI,30,),0) -> 0 | M25: =K25+L25 -> 0 | N25: =VLOOKUP($D25,'[1]DNC 재고 현황'!$F:$X,19,0) -> 68 | O25: =IFERROR(IF($M25/$V25>1,100%,IF($M25/$V25<0,0%,$M25/$V25)),"계획없음") -> 0 | P25: =$Y25+$AD25+$AI25+$AN25+$AI25 -> 0 | Q25: =IFERROR(W25/$M$2,0) -> 0 | R25: =IFERROR(M25/$Q25,0) -> 0 | S25: =IFERROR(N25/$Q25,0) -> 0 | T25: =IFERROR(TODAY()+(M25/Q25),"") | U25: =IF(S25<=1,"🔴판매없음",IF(S25<=40,"🟡주의",IF(S25<=60,"🟢안전","✅충분"))) -> 🔴판매없음 | V25: =IFERROR(SUMIF('[1](전체)FCST'!$D:$D,$D25,'[1](전체)FCST'!$H:$H),0) -> 95.783456 | W25: =IFERROR(VLOOKUP($D25,'[1]판매량,재고(피벗)'!$B:$C,2,0),0) -> 0 | X25: =IFERROR(W25/$M$2*$O$2,0) -> 0 | AA25: =MAX(SUM(N25-X25+Y25),0) -> 68 | AB25: =IFERROR(AA25/AC25,0) -> 0.71579768 | AC25: =IFERROR(VLOOKUP($D25,'[1]DNC 재고 현황'!$F:$V,14,0),0) -> 94.998911 | AD25: =SUMIFS('[1]입고 예정'!$C:$C,'[1]입고 예정'!$A:$A,모니터링!D25,'[1]입고 예정'!$F:$F,모니터링!AD$6) -> 0 | AF25: =MAX(IFERROR(SUM((AA25-AC25)+AD25),0),0) -> 0 | AG25: =IFERROR(AF25/AH25,0) -> 0 | AH25: =IFERROR(VLOOKUP($D25,'[1]DNC 재고 현황'!$F:$V,15,0),0) -> 95.783456 | AI25: =SUMIFS('[1]입고 예정'!$C:$C,'[1]입고 예정'!$A:$A,모니터링!D25,'[1]입고 예정'!$F:$F,모니터링!AI$6) -> 0 | AK25: =MAX(IFERROR(SUM((AF25-AH25)+AI25),0),0) -> 0 | AL25: =IFERROR(AK25/AM25,0) -> 0 | AM25: =IFERROR(VLOOKUP($D25,'[1]DNC 재고 현황'!$F:$V,16,0),0) -> 95 | AN25: =SUMIFS('[1]입고 예정'!$C:$C,'[1]입고 예정'!$A:$A,모니터링!D25,'[1]입고 예정'!$F:$F,모니터링!AN$6) -> 0 | AP25: =MAX(IFERROR(SUM((AK25-AM25)+AN25),0),0) -> 0 | AQ25: =IFERROR(AP25/AR25,0) -> 0 | AR25: =IFERROR(VLOOKUP($D25,'[1]DNC 재고 현황'!$F:$V,17,0),0) -> 95 | AS25: =SUMIFS('[1]입고 예정'!$C:$C,'[1]입고 예정'!$A:$A,모니터링!D25,'[1]입고 예정'!$F:$F,모니터링!AS$6) -> 0 | AU25: =MAX(IFERROR(AP25-AR25+AS25,0),0) -> 0 | AV25: =IFERROR(AU25/#REF!,0) -> 0
A26: - | B26: 완제품 | C26: 운영 | D26: 9313049 | E26: =VLOOKUP($D26,'[1]SAP 코드내역'!$A:$D,4,0) -> 멜라_토닝앰플파운데이션_23호베이지_15ml | H26: 신제품 | I26: 3461.2924 | J26: 27468.684 | K26: =IFERROR(VLOOKUP($D26,'[1]DNC 재고 현황'!$F:$AI,29,0),0) -> 2081 | L26: =IFERROR(VLOOKUP($D26,'[1]DNC 재고 현황'!$F:$AI,30,),0) -> 0 | M26: =K26+L26 -> 2081 | N26: =VLOOKUP($D26,'[1]DNC 재고 현황'!$F:$X,19,0) -> 2081 | O26: =IFERROR(IF($M26/$V26>1,100%,IF($M26/$V26<0,0%,$M26/$V26)),"계획없음") -> 1 | P26: =$Y26+$AD26+$AI26+$AN26+$AI26 -> 1900 | Q26: =IFERROR(W26/$M$2,0) -> 8.7142857 | R26: =IFERROR(M26/$Q26,0) -> 238.80328 | S26: =IFERROR(N26/$Q26,0) -> 238.80328 | T26: =IFERROR(TODAY()+(M26/Q26),"") -> 46358.803 | U26: =IF(S26<=1,"🔴판매없음",IF(S26<=40,"🟡주의",IF(S26<=60,"🟢안전","✅충분"))) -> ✅충분 | V26: =IFERROR(SUMIF('[1](전체)FCST'!$D:$D,$D26,'[1](전체)FCST'!$H:$H),0) -> 581.88469 | W26: =IFERROR(VLOOKUP($D26,'[1]판매량,재고(피벗)'!$B:$C,2,0),0) -> 61 | X26: =IFERROR(W26/$M$2*$O$2,0) -> 191.71429 | AA26: =MAX(SUM(N26-X26+Y26),0) -> 1889.2857 | AB26: =IFERROR(AA26/AC26,0) -> 3.2226423 | AC26: =IFERROR(VLOOKUP($D26,'[1]DNC 재고 현황'!$F:$V,14,0),0) -> 586.25362 | AD26: =SUMIFS('[1]입고 예정'!$C:$C,'[1]입고 예정'!$A:$A,모니터링!D26,'[1]입고 예정'!$F:$F,모니터링!AD$6) -> 1900 | AF26: =MAX(IFERROR(SUM((AA26-AC26)+AD26),0),0) -> 3203.0321 | AG26: =IFERROR(AF26/AH26,0) -> 5.5045822 | AH26: =IFERROR(VLOOKUP($D26,'[1]DNC 재고 현황'!$F:$V,15,0),0) -> 581.88469 | AI26: =SUMIFS('[1]입고 예정'!$C:$C,'[1]입고 예정'!$A:$A,모니터링!D26,'[1]입고 예정'!$F:$F,모니터링!AI$6) -> 0 | AK26: =MAX(IFERROR(SUM((AF26-AH26)+AI26),0),0) -> 2621.1474 | AL26: =IFERROR(AK26/AM26,0) -> 4.4950677 | AM26: =IFERROR(VLOOKUP($D26,'[1]DNC 재고 현황'!$F:$V,16,0),0) -> 583.11633 | AN26: =SUMIFS('[1]입고 예정'!$C:$C,'[1]입고 예정'!$A:$A,모니터링!D26,'[1]입고 예정'!$F:$F,모니터링!AN$6) -> 0 | AP26: =MAX(IFERROR(SUM((AK26-AM26)+AN26),0),0) -> 2038.0311 | AQ26: =IFERROR(AP26/AR26,0) -> 3.4950677 | AR26: =IFERROR(VLOOKUP($D26,'[1]DNC 재고 현황'!$F:$V,17,0),0) -> 583.11633 | AS26: =SUMIFS('[1]입고 예정'!$C:$C,'[1]입고 예정'!$A:$A,모니터링!D26,'[1]입고 예정'!$F:$F,모니터링!AS$6) -> 0 | AU26: =MAX(IFERROR(AP26-AR26+AS26,0),0) -> 1454.9147 | AV26: =IFERROR(AU26/#REF!,0) -> 0
